Workbook

Sheet Cost Estimate
A2: Project Title: Risk Management, Financial Analysis & Administrative Support
A3: Solicitation: 47QACA26R0306
A4: Description of Cost Elements
A5: Direct Labor (list labor categories) | E5: Number of Employees | F5: Estimated Hours | G5: Rate per Hour ($) | H5: Estimated Cost ($) | I5: Total Estimated Cost ($)
A6: On Site Supervisor | E6: 1 | F6: 2080 | H6: =F6*G6 -> 0
A7: Financial Analyst | E7: 2 | F7: 4160 | H7: =F7*G7 -> 0
A8: Administrative Assistant | E8: 1 | F8: 2080 | H8: =F8*G8 -> 0
A9: Program Analyst I | E9: 1 | F9: 2080 | H9: =F9*G9 -> 0
A10: Program Analyst II | E10: 2 | F10: 4160 | H10: =F10*G10 -> 0
A11: Program Analyst III | E11: 1 | F11: 2080 | H11: =F11*G11 -> 0
D13: Total Base Amount | F13: =SUM(F6:F12) -> 16640 | I13: =SUM(H6:H12) -> 0
A16: =A6 -> On Site Supervisor | E16: 1 | F16: 2080 | H16: =F16*G16 -> 0
A17: =A7 -> Financial Analyst | E17: 2 | F17: 4160 | H17: =F17*G17 -> 0
A18: =A8 -> Administrative Assistant | E18: 1 | F18: =F9 -> 2080 | H18: =F18*G18 -> 0
A19: Program Analyst I | E19: 1 | F19: 2080 | H19: =F19*G19 -> 0
A20: Program Analyst II | E20: 2 | F20: 4160 | H20: =F20*G20 -> 0
A21: Program Analyst III | E21: 1 | F21: 2080 | H21: =F21*G21 -> 0
D22: Option Year 1 Amount | F22: =SUM(F15:F21) -> 16640 | I22: =SUM(H15:H21) -> 0
F24: =F15 -> 0
A25: =A16 -> On Site Supervisor | E25: 1 | F25: =F16 -> 2080 | H25: =F25*G25 -> 0
A26: =A17 -> Financial Analyst | E26: 2 | F26: =F17 -> 4160 | H26: =F26*G26 -> 0
A27: Administrative Assistant | E27: 1 | F27: =F18 -> 2080 | H27: =F27*G27 -> 0
A28: Program Analyst I | E28: 1 | F28: 2080 | H28: =F28*G28 -> 0
A29: Program Analyst II | E29: 2 | F29: 4160 | H29: =F29*G29 -> 0
A30: Program Analyst III | E30: 1 | F30: 2080 | H30: =F30*G30 -> 0
D31: Option Year 2 Amount | F31: =SUM(F24:F30) -> 16640 | I31: =SUM(H24:H30) -> 0
F33: =F24 -> 0
A34: =A25 -> On Site Supervisor | E34: 1 | F34: =F25 -> 2080 | H34: =F34*G34 -> 0
A35: =A26 -> Financial Analyst | E35: 2 | F35: =F26 -> 4160 | H35: =F35*G35 -> 0
A36: Administrative Assistant | E36: 1 | F36: =F27 -> 2080 | H36: =F36*G36 -> 0
A37: Program Analyst I | E37: 1 | F37: 2080 | H37: =F37*G37 -> 0
A38: Program Analyst II | E38: 2 | F38: 4160 | H38: =F38*G38 -> 0
A39: Program Analyst III | E39: 1 | F39: 2080 | H39: =F39*G39 -> 0
D40: Option Year 3 Amount | F40: =SUM(F33:F39) -> 16640 | I40: =SUM(H33:H39) -> 0
A42: =A34 -> On Site Supervisor | E42: 1 | F42: 2080 | H42: =F42*G42 -> 0
A43: =A35 -> Financial Analyst | E43: 2 | F43: =F35 -> 4160 | H43: =F43*G43 -> 0
A44: Administrative Assistant | E44: 1 | F44: =F36 -> 2080 | H44: =F44*G44 -> 0
A45: Program Analyst I | E45: 1 | F45: 2080 | H45: =F45*G45 -> 0
A46: Program Analyst II | E46: 2 | F46: 4160 | H46: =F46*G46 -> 0
A47: Program Analyst III | E47: 1 | F47: 2080 | H47: =F47*G47 -> 0
...

Sheet Sheet2
A1: Year | B1: Total Cost
A2: Base | B2: ='Cost Estimate'!I13 -> 0
A3: Option Year 1 | B3: ='Cost Estimate'!I22 -> 0
A4: Option Year 2 | B4: ='Cost Estimate'!I31 -> 0
A5: Option Year 3 | B5: ='Cost Estimate'!I40 -> 0
A6: Option Year 4 | B6: ='Cost Estimate'!I48 -> 0
A7: Total | B7: =SUM(B2:B6) -> 0
A12: Year | B12: Total Cost
A13: Base | B13: =#REF! -> #REF!
A14: Option Year 1 | B14: =#REF! -> #REF!
A15: Total | B15: =SUM(B13:B14) -> #REF!

Sheet -
