Workbook

Sheet Proposal Summary
A1: PRICE PROPOSAL SUMMARY - DO NOT ALTER OR MANIPULATE THIS TAB IN ANY WAY
A2: Project Title
A3: APS Single Award
A6: Total - T&M
A7: =SUM(D10:D16) -> 0
A9: Contract Period | B9: Period of Performance Start Date | C9: Period of Performance End Date | D9: Total
A10: Base Period | B10: 46433 | C10: 46613 | D10: ='Base Period'!CR60 -> 0
A11: Option Period 1 | B11: 46614 | C11: 46979 | D11: ='Option Period 1'!CR60 -> 0
A12: Option Period 2 | B12: 46980 | C12: 47344 | D12: ='Option Period 2'!CR60 -> 0
A13: Option Period 3 | B13: 47345 | C13: 47709 | D13: ='Option Period 3'!CR60 -> 0
A14: Option Period 4 | B14: 47710 | C14: 48074 | D14: ='Option Period 4'!CR60 -> 0
A15: Option Period 5 | B15: 48075 | C15: 48258 | D15: ='Option Period 5'!CR60 -> 0
A16: Option Period 6 (-8 Option) | B16: 48259 | C16: 48440 | D16: ='Option Period 6'!CR60 -> 0
A17: TOTAL CONTRACT LABOR | B17: 46433 | C17: 48440 | D17: =SUM(D10:D16) -> 0
A20: Total - Reimbursable Travel
A21: =SUM(D24:D30) -> 16500000
A23: Contract Period | B23: Period of Performance Start Date | C23: Period of Performance End Date | D23: Total | E23: GOVERNMENT PLUG NUMBERS
A24: Base Period | B24: 46433 | C24: 46613 | D24: 1500000
A25: Option Period 1 | B25: 46614 | C25: 46979 | D25: 3000000
A26: Option Period 2 | B26: 46980 | C26: 47344 | D26: 3000000
A27: Option Period 3 | B27: 47345 | C27: 47709 | D27: 3000000
A28: Option Period 4 | B28: 47710 | C28: 48074 | D28: 3000000
A29: Option Period 5 | B29: 48075 | C29: 48258 | D29: 1500000
A30: Option Period 6 (-8 Option) | B30: 48259 | C30: 48440 | D30: 1500000
A31: TOTAL CONTRACT TRAVEL | B31: 46433 | C31: 48440 | D31: =SUM(D24:D30) -> 16500000
A34: TOTAL EVALUATED PRICE
A35: =SUM(D38:D44) -> 16500000
A37: Contract Period | B37: Period of Performance Start Date | C37: Period of Performance End Date | D37: Total
A38: Base Period | B38: 46433 | C38: 46613 | D38: =D10+D24 -> 1500000
A39: Option Period 1 | B39: 46614 | C39: 46979 | D39: =D11+D25 -> 3000000
A40: Option Period 2 | B40: 46980 | C40: 47344 | D40: =D12+D26 -> 3000000
A41: Option Period 3 | B41: 47345 | C41: 47709 | D41: =D13+D27 -> 3000000
A42: Option Period 4 | B42: 47710 | C42: 48074 | D42: =D14+D28 -> 3000000
A43: Option Period 5 | B43: 48075 | C43: 48258 | D43: =D15+D29 -> 1500000
A44: Option Period 6 (-8 Option) | B44: 48259 | C44: 48440 | D44: =D16+D30 -> 1500000
A45: TOTAL CONTRACT VALUE | B45: 46433 | C45: 48440 | D45: =SUM(D38:D44) -> 16500000

Sheet Base Period
A1: Base Period
A2: Contract Period | B2: Period of Performance Start Date | C2: Period of Performance End Date | F2: Escalation Rate | G2: Total
A3: Base Period | B3: 46433 | C3: 46613 | F3: 0 | G3: =U59 -> 0
A6: Direct Labor
A10: Occupation | B10: Offeror Labor Category | C10: GSA Occupation Level | D10: Escalation Applied (Y/N) | E10: SCA Exempt (Y/N) | F10: SCA Base Rate | G10: SIM HRS Orlando | H10: SIM Rate Orlando | I10: SIM Orlando Rate Burdened | J10: SIM Orlando Subtotal | K10: SIM HRS Ft Campbell | L10: SIM Ft. Campbell Rate | M10: SIM Ft. Campbell Burdened | N10: SIM Ft. Campell Subtotal | O10: TRADE HRS Orlando | P10: TRADE Orlando Rate | Q10: TRADE Orlando Rate Burdened | R10: TRADE Orlando Subtotal | S10: TRADE HRS Germany | T10: TRADE Rate Germany | U10: TRADE Rate Germany Burdened | V10: TRADE Germany Subtotal | W10: TRADE HRS Ft. Hood | X10: TRADE Rate Ft. Hood | Y10: TRADE Rate Ft Hood Burdened | Z10: TRADE Ft. Hood Subtotal | AA10: TRADE HRS Ft. Irwin | AB10: TRADE Rate Ft. Irwin | AC10: TRADE Rate Ft. Irwin Burdened | AD10: TRADE Ft. Irwin Subtotal | AE10: TRADE HRS Ft. Polk | AF10: TRADE Rate Ft. Polk | AG10: TRADE Rate Ft. Polk Burdened | AH10: TRADE Ft. Polk Subtotal | AI10: IPO HRS Orlando | AJ10: IPO Orlando Rate | AK10: IPO Orlando Rate Burdened | AL10: IPO Orlando Subtotal | AM10: IPO HRS Ft. Campbell | AN10: IPO Ft. Campbell Rate | AO10: IPO Rate Ft. Campbell Burdened | AP10: IPO Ft. Campbell Subtotal | AQ10: TSO HRS Orlando | AR10: TSO Rate | AS10: TSO Rate Burdened | AT10: TSO Subtotal | AU10: TSO HRS Ft. Bragg | AV10: TSO Rate Ft. Bragg | AW10: TSO Rate Ft. Bragg Burdened | AX10: TSO Ft. Bragg Subtotal | AY10: TSO HRS Ft Drum | AZ10: TSO Rate Ft. Drum | BA10: TSO Rate Ft. Drum Burdened | BB10: TSO Ft. Drum Subtotal | BC10: TSO HRS Ft. Rucker | BD10: TSO Rate Ft. Rucker | BE10: TSO Rate Ft. Rucker Burdened | BF10: TSO Ft. Rucker Subtotal | BG10: TSO HRS Ft. Polk | BH10: TSO Rate Ft. Polk | BI10: TSO Rate Ft. Polk Burdened | BJ10: TSO Ft. Polk Subtotal | BK10: TSO HRS Ft. Irwin | BL10: TSO Rate Ft. Irwin | BM10: TSO Rate Ft. Irwin Burdened | BN10: TSO Ft. Irwin Subtotal | BO10: TSO HRS Germany | BP10: TSO Rate Germany | BQ10: TSO Rate Germany Burdened | BR10: TSO Germany Subtotal | BS10: TSO HRS S. Korea | BT10: TSO Rate S. Korea | BU10: TSO Rate S. Korea Burdened | BV10: TSO S. Korea Subtotal | BW10: HQ HRS (Orlando, FL) | BX10: HQ Rate | BY10: HQ Rate Burdened | BZ10: HQ Subtotal | CA10: TSMO HRS Orlando | CB10: TSMO Rate | CC10: TSMO Rate Burdened | CD10: TSMO Subtotal | CE10: TSMO HRS Huntsville, AL | CF10: TSMO Huntsville, AL. Rate | CG10: Huntsville, Alabama Rate (Burdened) | CH10: TSO Huntsville, AL Subtotal | CI10: Agile Administration HRS (Offeror Defined Location) | CJ10: Agile Administration Rate | CK10: Agile Administration Rate Burdened | CL10: Agile Administration Subtotal | CM10: Fringe % | CN10: Overhead % | CO10: G&A % | CP10: Profit % | CQ10: Burden Rate | CR10: Total
A11: 49-9099 Installation, Maintenance, and Repair Workers, All Other | C11: Subject Matter Expert (SME) | I11: =H11*CQ11 -> 0 | J11: =G11*I11 -> 0 | M11: =L11*CQ11 -> 0 | N11: =K11*M11 -> 0 | Q11: =P11*CQ11 -> 0 | R11: =O11*Q11 -> 0 | U11: =T11*CQ11 -> 0 | V11: =S11*U11 -> 0 | Y11: =X11*CQ11 -> 0 | Z11: =W11*Y11 -> 0 | AC11: =AB11*CQ11 -> 0 | AD11: =AA11*AC11 -> 0 | AG11: =AF11*CQ11 -> 0 | AH11: =AE11*AG11 -> 0 | AK11: =AJ11*CQ11 -> 0 | AL11: =AI11*AK11 -> 0 | AO11: =AN11*CQ11 -> 0 | AP11: =AM11*AO11 -> 0 | AS11: =AR11*CQ11 -> 0 | AT11: =AQ11*AS11 -> 0 | AW11: =AV11*CQ11 -> 0 | AX11: =AU11*AW11 -> 0 | BA11: =AZ11*CQ11 -> 0 | BB11: =AY11*BA11 -> 0 | BE11: =BD11*CQ11 -> 0 | BF11: =BC11*BE11 -> 0 | BI11: =BH11*CQ11 -> 0 | BJ11: =BG11*BI11 -> 0 | BM11: =BL11*CQ11 -> 0 | BN11: =BK11*BM11 -> 0 | BQ11: =BP11*CQ11 -> 0 | BR11: =BO11*BQ11 -> 0 | BU11: =BT11*CQ11 -> 0 | BV11: =BS11*BU11 -> 0 | BW11: 240 | BY11: =BX11*CQ11 -> 0 | BZ11: =BW11*BY11 -> 0 | CC11: =CB11*CQ11 -> 0 | CD11: =CA11*CC11 -> 0 | CG11: =CF11*CQ11 -> 0 | CH11: =CE11*CG11 -> 0 | CK11: =CJ11*CQ11 -> 0 | CL11: =CI11*CK11 -> 0 | CM11: 0.1 | CN11: 0.15 | CO11: 0.05 | CP11: 0.1 | CQ11: =(1+CM11)*(1+CN11)*(1+CO11)*(1+CP11) -> 1.461075 | CR11: =J11+N11+R11+V11+Z11+AD11+AH11+AL11+AP11+AT11+AX11+BB11+BF11+BJ11+BN11+BR11+BV11+BZ11+CD11+CH11+CL11 -> 0
A12: 49-9099 Installation, Maintenance, and Repair Workers, All Other | C12: Journeyman (3–10 yrs) | I12: =H12*CQ12 -> 0 | J12: =G12*I12 -> 0 | M12: =L12*CQ12 -> 0 | N12: =K12*M12 -> 0 | Q12: =P12*CQ12 -> 0 | R12: =O12*Q12 -> 0 | U12: =T12*CQ12 -> 0 | V12: =S12*U12 -> 0 | Y12: =X12*CT12 -> 0 | Z12: =W12*Y12 -> 0 | AC12: =AB12*CW12 -> 0 | AD12: =AA12*AC12 -> 0 | AG12: =AF12*CZ12 -> 0 | AH12: =AE12*AG12 -> 0 | AK12: =AJ12*CQ12 -> 0 | AL12: =AI12*AK12 -> 0 | AO12: =AN12*CQ12 -> 0 | AP12: =AM12*AO12 -> 0 | AS12: =AR12*CQ12 -> 0 | AT12: =AQ12*AS12 -> 0 | AW12: =AV12*CQ12 -> 0 | AX12: =AU12*AW12 -> 0 | BA12: =AZ12*CQ12 -> 0 | BB12: =AY12*BA12 -> 0 | BE12: =BD12*CQ12 -> 0 | BF12: =BC12*BE12 -> 0 | BI12: =BH12*CQ12 -> 0 | BJ12: =BG12*BI12 -> 0 | BM12: =BL12*CQ12 -> 0 | BN12: =BK12*BM12 -> 0 | BQ12: =BP12*CQ12 -> 0 | BR12: =BO12*BQ12 -> 0 | BU12: =BT12*CQ12 -> 0 | BV12: =BS12*BU12 -> 0 | BW12: 240 | BY12: =BX12*CQ12 -> 0 | BZ12: =BW12*BY12 -> 0 | CC12: =CB12*CQ12 -> 0 | CD12: =CA12*CC12 -> 0 | CG12: =CF12*CQ12 -> 0 | CH12: =CE12*CG12 -> 0 | CK12: =CJ12*CQ12 -> 0 | CL12: =CI12*CK12 -> 0 | CQ12: =(1+CM12)*(1+CN12)*(1+CO12)*(1+CP12) -> 1 | CR12: =J12+N12+R12+V12+Z12+AD12+AH12+AL12+AP12+AT12+AX12+BB12+BF12+BJ12+BN12+BR12+BV12+BZ12+CD12+CH12+CL12 -> 0
A13: 27-3042 Technical Writers | C13: Journeyman (3–10 yrs) | I13: =H13*CQ13 -> 0 | J13: =G13*I13 -> 0 | M13: =L13*CQ13 -> 0 | N13: =K13*M13 -> 0 | O13: 1920 | Q13: =P13*CQ13 -> 0 | R13: =O13*Q13 -> 0 | U13: =T13*CQ13 -> 0 | V13: =S13*U13 -> 0 | Y13: =X13*CT13 -> 0 | Z13: =W13*Y13 -> 0 | AC13: =AB13*CW13 -> 0 | AD13: =AA13*AC13 -> 0 | AG13: =AF13*CZ13 -> 0 | AH13: =AE13*AG13 -> 0 | AK13: =AJ13*CQ13 -> 0 | AL13: =AI13*AK13 -> 0 | AO13: =AN13*CQ13 -> 0 | AP13: =AM13*AO13 -> 0 | AS13: =AR13*CQ13 -> 0 | AT13: =AQ13*AS13 -> 0 | AW13: =AV13*CQ13 -> 0 | AX13: =AU13*AW13 -> 0 | BA13: =AZ13*CQ13 -> 0 | BB13: =AY13*BA13 -> 0 | BE13: =BD13*CQ13 -> 0 | BF13: =BC13*BE13 -> 0 | BI13: =BH13*CQ13 -> 0 | BJ13: =BG13*BI13 -> 0 | BM13: =BL13*CQ13 -> 0 | BN13: =BK13*BM13 -> 0 | BQ13: =BP13*CQ13 -> 0 | BR13: =BO13*BQ13 -> 0 | BU13: =BT13*CQ13 -> 0 | BV13: =BS13*BU13 -> 0 | BY13: =BX13*CQ13 -> 0 | BZ13: =BW13*BY13 -> 0 | CC13: =CB13*CQ13 -> 0 | CD13: =CA13*CC13 -> 0 | CG13: =CF13*CQ13 -> 0 | CH13: =CE13*CG13 -> 0 | CK13: =CJ13*CQ13 -> 0 | CL13: =CI13*CK13 -> 0 | CQ13: =(1+CM13)*(1+CN13)*(1+CO13)*(1+CP13) -> 1 | CR13: =J13+N13+R13+V13+Z13+AD13+AH13+AL13+AP13+AT13+AX13+BB13+BF13+BJ13+BN13+BR13+BV13+BZ13+CD13+CH13+CL13 -> 0
A14: 27-3042 Technical Writers | C14: Senior (>10 yrs) | I14: =H14*CQ14 -> 0 | J14: =G14*I14 -> 0 | M14: =L14*CQ14 -> 0 | N14: =K14*M14 -> 0 | O14: 960 | Q14: =P14*CQ14 -> 0 | R14: =O14*Q14 -> 0 | U14: =T14*CQ14 -> 0 | V14: =S14*U14 -> 0 | Y14: =X14*CT14 -> 0 | Z14: =W14*Y14 -> 0 | AC14: =AB14*CW14 -> 0 | AD14: =AA14*AC14 -> 0 | AG14: =AF14*CZ14 -> 0 | AH14: =AE14*AG14 -> 0 | AK14: =AJ14*CQ14 -> 0 | AL14: =AI14*AK14 -> 0 | AO14: =AN14*CQ14 -> 0 | AP14: =AM14*AO14 -> 0 | AS14: =AR14*CQ14 -> 0 | AT14: =AQ14*AS14 -> 0 | AW14: =AV14*CQ14 -> 0 | AX14: =AU14*AW14 -> 0 | BA14: =AZ14*CQ14 -> 0 | BB14: =AY14*BA14 -> 0 | BE14: =BD14*CQ14 -> 0 | BF14: =BC14*BE14 -> 0 | BI14: =BH14*CQ14 -> 0 | BJ14: =BG14*BI14 -> 0 | BM14: =BL14*CQ14 -> 0 | BN14: =BK14*BM14 -> 0 | BQ14: =BP14*CQ14 -> 0 | BR14: =BO14*BQ14 -> 0 | BU14: =BT14*CQ14 -> 0 | BV14: =BS14*BU14 -> 0 | BY14: =BX14*CQ14 -> 0 | BZ14: =BW14*BY14 -> 0 | CC14: =CB14*CQ14 -> 0 | CD14: =CA14*CC14 -> 0 | CG14: =CF14*CQ14 -> 0 | CH14: =CE14*CG14 -> 0 | CK14: =CJ14*CQ14 -> 0 | CL14: =CI14*CK14 -> 0 | CQ14: =(1+CM14)*(1+CN14)*(1+CO14)*(1+CP14) -> 1 | CR14: =J14+N14+R14+V14+Z14+AD14+AH14+AL14+AP14+AT14+AX14+BB14+BF14+BJ14+BN14+BR14+BV14+BZ14+CD14+CH14+CL14 -> 0
A15: 27-3031 Public Relations Specialists** | C15: Senior (>10 yrs) | I15: =H15*CQ15 -> 0 | J15: =G15*I15 -> 0 | M15: =L15*CQ15 -> 0 | N15: =K15*M15 -> 0 | Q15: =P15*CQ15 -> 0 | R15: =O15*Q15 -> 0 | U15: =T15*CQ15 -> 0 | V15: =S15*U15 -> 0 | Y15: =X15*CT15 -> 0 | Z15: =W15*Y15 -> 0 | AC15: =AB15*CW15 -> 0 | AD15: =AA15*AC15 -> 0 | AG15: =AF15*CZ15 -> 0 | AH15: =AE15*AG15 -> 0 | AK15: =AJ15*CQ15 -> 0 | AL15: =AI15*AK15 -> 0 | AO15: =AN15*CQ15 -> 0 | AP15: =AM15*AO15 -> 0 | AS15: =AR15*CQ15 -> 0 | AT15: =AQ15*AS15 -> 0 | AW15: =AV15*CQ15 -> 0 | AX15: =AU15*AW15 -> 0 | BA15: =AZ15*CQ15 -> 0 | BB15: =AY15*BA15 -> 0 | BE15: =BD15*CQ15 -> 0 | BF15: =BC15*BE15 -> 0 | BI15: =BH15*CQ15 -> 0 | BJ15: =BG15*BI15 -> 0 | BM15: =BL15*CQ15 -> 0 | BN15: =BK15*BM15 -> 0 | BQ15: =BP15*CQ15 -> 0 | BR15: =BO15*BQ15 -> 0 | BU15: =BT15*CQ15 -> 0 | BV15: =BS15*BU15 -> 0 | BY15: =BX15*CQ15 -> 0 | BZ15: =BW15*BY15 -> 0 | CC15: =CB15*CQ15 -> 0 | CD15: =CA15*CC15 -> 0 | CG15: =CF15*CQ15 -> 0 | CH15: =CE15*CG15 -> 0 | CK15: =CJ15*CQ15 -> 0 | CL15: =CI15*CK15 -> 0 | CQ15: =(1+CM15)*(1+CN15)*(1+CO15)*(1+CP15) -> 1 | CR15: =J15+N15+R15+V15+Z15+AD15+AH15+AL15+AP15+AT15+AX15+BB15+BF15+BJ15+BN15+BR15+BV15+BZ15+CD15+CH15+CL15 -> 0
A16: 17-3029 Engineering Technologists and Technicians | C16: Senior (>10 yrs) | I16: =H16*CQ16 -> 0 | J16: =G16*I16 -> 0 | M16: =L16*CQ16 -> 0 | N16: =K16*M16 -> 0 | Q16: =P16*CQ16 -> 0 | R16: =O16*Q16 -> 0 | U16: =T16*CQ16 -> 0 | V16: =S16*U16 -> 0 | Y16: =X16*CT16 -> 0 | Z16: =W16*Y16 -> 0 | AC16: =AB16*CW16 -> 0 | AD16: =AA16*AC16 -> 0 | AG16: =AF16*CZ16 -> 0 | AH16: =AE16*AG16 -> 0 | AK16: =AJ16*CQ16 -> 0 | AL16: =AI16*AK16 -> 0 | AO16: =AN16*CQ16 -> 0 | AP16: =AM16*AO16 -> 0 | AS16: =AR16*CQ16 -> 0 | AT16: =AQ16*AS16 -> 0 | AW16: =AV16*CQ16 -> 0 | AX16: =AU16*AW16 -> 0 | BA16: =AZ16*CQ16 -> 0 | BB16: =AY16*BA16 -> 0 | BE16: =BD16*CQ16 -> 0 | BF16: =BC16*BE16 -> 0 | BI16: =BH16*CQ16 -> 0 | BJ16: =BG16*BI16 -> 0 | BM16: =BL16*CQ16 -> 0 | BN16: =BK16*BM16 -> 0 | BQ16: =BP16*CQ16 -> 0 | BR16: =BO16*BQ16 -> 0 | BU16: =BT16*CQ16 -> 0 | BV16: =BS16*BU16 -> 0 | BY16: =BX16*CQ16 -> 0 | BZ16: =BW16*BY16 -> 0 | CA16: 960 | CC16: =CB16*CQ16 -> 0 | CD16: =CA16*CC16 -> 0 | CG16: =CF16*CQ16 -> 0 | CH16: =CE16*CG16 -> 0 | CK16: =CJ16*CQ16 -> 0 | CL16: =CI16*CK16 -> 0 | CQ16: =(1+CM16)*(1+CN16)*(1+CO16)*(1+CP16) -> 1 | CR16: =J16+N16+R16+V16+Z16+AD16+AH16+AL16+AP16+AT16+AX16+BB16+BF16+BJ16+BN16+BR16+BV16+BZ16+CD16+CH16+CL16 -> 0
A17: 17-2199 Engineers, All Other | C17: Subject Matter Expert (SME) | G17: 960 | I17: =H17*CQ17 -> 0 | J17: =G17*I17 -> 0 | M17: =L17*CQ17 -> 0 | N17: =K17*M17 -> 0 | Q17: =P17*CQ17 -> 0 | R17: =O17*Q17 -> 0 | U17: =T17*CQ17 -> 0 | V17: =S17*U17 -> 0 | Y17: =X17*CT17 -> 0 | Z17: =W17*Y17 -> 0 | AC17: =AB17*CW17 -> 0 | AD17: =AA17*AC17 -> 0 | AG17: =AF17*CZ17 -> 0 | AH17: =AE17*AG17 -> 0 | AK17: =AJ17*CQ17 -> 0 | AL17: =AI17*AK17 -> 0 | AO17: =AN17*CQ17 -> 0 | AP17: =AM17*AO17 -> 0 | AS17: =AR17*CQ17 -> 0 | AT17: =AQ17*AS17 -> 0 | AW17: =AV17*CQ17 -> 0 | AX17: =AU17*AW17 -> 0 | BA17: =AZ17*CQ17 -> 0 | BB17: =AY17*BA17 -> 0 | BE17: =BD17*CQ17 -> 0 | BF17: =BC17*BE17 -> 0 | BI17: =BH17*CQ17 -> 0 | BJ17: =BG17*BI17 -> 0 | BM17: =BL17*CQ17 -> 0 | BN17: =BK17*BM17 -> 0 | BQ17: =BP17*CQ17 -> 0 | BR17: =BO17*BQ17 -> 0 | BU17: =BT17*CQ17 -> 0 | BV17: =BS17*BU17 -> 0 | BY17: =BX17*CQ17 -> 0 | BZ17: =BW17*BY17 -> 0 | CC17: =CB17*CQ17 -> 0 | CD17: =CA17*CC17 -> 0 | CG17: =CF17*CQ17 -> 0 | CH17: =CE17*CG17 -> 0 | CK17: =CJ17*CQ17 -> 0 | CL17: =CI17*CK17 -> 0 | CQ17: =(1+CM17)*(1+CN17)*(1+CO17)*(1+CP17) -> 1 | CR17: =J17+N17+R17+V17+Z17+AD17+AH17+AL17+AP17+AT17+AX17+BB17+BF17+BJ17+BN17+BR17+BV17+BZ17+CD17+CH17+CL17 -> 0
A18: 17-2199 Engineers, All Other | C18: Journeyman (3–10 yrs) | G18: 2880 | I18: =H18*CQ18 -> 0 | J18: =G18*I18 -> 0 | M18: =L18*CQ18 -> 0 | N18: =K18*M18 -> 0 | Q18: =P18*CQ18 -> 0 | R18: =O18*Q18 -> 0 | U18: =T18*CQ18 -> 0 | V18: =S18*U18 -> 0 | Y18: =X18*CT18 -> 0 | Z18: =W18*Y18 -> 0 | AC18: =AB18*CW18 -> 0 | AD18: =AA18*AC18 -> 0 | AG18: =AF18*CZ18 -> 0 | AH18: =AE18*AG18 -> 0 | AI18: 960 | AK18: =AJ18*CQ18 -> 0 | AL18: =AI18*AK18 -> 0 | AO18: =AN18*CQ18 -> 0 | AP18: =AM18*AO18 -> 0 | AS18: =AR18*CQ18 -> 0 | AT18: =AQ18*AS18 -> 0 | AW18: =AV18*CQ18 -> 0 | AX18: =AU18*AW18 -> 0 | BA18: =AZ18*CQ18 -> 0 | BB18: =AY18*BA18 -> 0 | BE18: =BD18*CQ18 -> 0 | BF18: =BC18*BE18 -> 0 | BI18: =BH18*CQ18 -> 0 | BJ18: =BG18*BI18 -> 0 | BM18: =BL18*CQ18 -> 0 | BN18: =BK18*BM18 -> 0 | BQ18: =BP18*CQ18 -> 0 | BR18: =BO18*BQ18 -> 0 | BU18: =BT18*CQ18 -> 0 | BV18: =BS18*BU18 -> 0 | BY18: =BX18*CQ18 -> 0 | BZ18: =BW18*BY18 -> 0 | CC18: =CB18*CQ18 -> 0 | CD18: =CA18*CC18 -> 0 | CG18: =CF18*CQ18 -> 0 | CH18: =CE18*CG18 -> 0 | CK18: =CJ18*CQ18 -> 0 | CL18: =CI18*CK18 -> 0 | CQ18: =(1+CM18)*(1+CN18)*(1+CO18)*(1+CP18) -> 1 | CR18: =J18+N18+R18+V18+Z18+AD18+AH18+AL18+AP18+AT18+AX18+BB18+BF18+BJ18+BN18+BR18+BV18+BZ18+CD18+CH18+CL18 -> 0
A19: 17-2199 Engineers, All Other | C19: Senior (>10 yrs) | G19: 10560 | I19: =H19*CQ19 -> 0 | J19: =G19*I19 -> 0 | M19: =L19*CQ19 -> 0 | N19: =K19*M19 -> 0 | Q19: =P19*CQ19 -> 0 | R19: =O19*Q19 -> 0 | U19: =T19*CQ19 -> 0 | V19: =S19*U19 -> 0 | Y19: =X19*CT19 -> 0 | Z19: =W19*Y19 -> 0 | AC19: =AB19*CW19 -> 0 | AD19: =AA19*AC19 -> 0 | AG19: =AF19*CZ19 -> 0 | AH19: =AE19*AG19 -> 0 | AK19: =AJ19*CQ19 -> 0 | AL19: =AI19*AK19 -> 0 | AO19: =AN19*CQ19 -> 0 | AP19: =AM19*AO19 -> 0 | AS19: =AR19*CQ19 -> 0 | AT19: =AQ19*AS19 -> 0 | AW19: =AV19*CQ19 -> 0 | AX19: =AU19*AW19 -> 0 | BA19: =AZ19*CQ19 -> 0 | BB19: =AY19*BA19 -> 0 | BE19: =BD19*CQ19 -> 0 | BF19: =BC19*BE19 -> 0 | BI19: =BH19*CQ19 -> 0 | BJ19: =BG19*BI19 -> 0 | BM19: =BL19*CQ19 -> 0 | BN19: =BK19*BM19 -> 0 | BQ19: =BP19*CQ19 -> 0 | BR19: =BO19*BQ19 -> 0 | BU19: =BT19*CQ19 -> 0 | BV19: =BS19*BU19 -> 0 | BY19: =BX19*CQ19 -> 0 | BZ19: =BW19*BY19 -> 0 | CC19: =CB19*CQ19 -> 0 | CD19: =CA19*CC19 -> 0 | CG19: =CF19*CQ19 -> 0 | CH19: =CE19*CG19 -> 0 | CK19: =CJ19*CQ19 -> 0 | CL19: =CI19*CK19 -> 0 | CQ19: =(1+CM19)*(1+CN19)*(1+CO19)*(1+CP19) -> 1 | CR19: =J19+N19+R19+V19+Z19+AD19+AH19+AL19+AP19+AT19+AX19+BB19+BF19+BJ19+BN19+BR19+BV19+BZ19+CD19+CH19+CL19 -> 0
A20: 17-2072 Electronics Engineers, Except Computer | C20: Journeyman | I20: =H20*CQ20 -> 0 | J20: =G20*I20 -> 0 | M20: =L20*CQ20 -> 0 | N20: =K20*M20 -> 0 | O20: 5760 | Q20: =P20*CQ20 -> 0 | R20: =O20*Q20 -> 0 | U20: =T20*CQ20 -> 0 | V20: =S20*U20 -> 0 | Y20: =X20*CT20 -> 0 | Z20: =W20*Y20 -> 0 | AC20: =AB20*CW20 -> 0 | AD20: =AA20*AC20 -> 0 | AG20: =AF20*CZ20 -> 0 | AH20: =AE20*AG20 -> 0 | AK20: =AJ20*CQ20 -> 0 | AL20: =AI20*AK20 -> 0 | AO20: =AN20*CQ20 -> 0 | AP20: =AM20*AO20 -> 0 | AS20: =AR20*CQ20 -> 0 | AT20: =AQ20*AS20 -> 0 | AW20: =AV20*CQ20 -> 0 | AX20: =AU20*AW20 -> 0 | BA20: =AZ20*CQ20 -> 0 | BB20: =AY20*BA20 -> 0 | BE20: =BD20*CQ20 -> 0 | BF20: =BC20*BE20 -> 0 | BI20: =BH20*CQ20 -> 0 | BJ20: =BG20*BI20 -> 0 | BM20: =BL20*CQ20 -> 0 | BN20: =BK20*BM20 -> 0 | BQ20: =BP20*CQ20 -> 0 | BR20: =BO20*BQ20 -> 0 | BU20: =BT20*CQ20 -> 0 | BV20: =BS20*BU20 -> 0 | BY20: =BX20*CQ20 -> 0 | BZ20: =BW20*BY20 -> 0 | CC20: =CB20*CQ20 -> 0 | CD20: =CA20*CC20 -> 0 | CG20: =CF20*CQ20 -> 0 | CH20: =CE20*CG20 -> 0 | CK20: =CJ20*CQ20 -> 0 | CL20: =CI20*CK20 -> 0 | CQ20: =(1+CM20)*(1+CN20)*(1+CO20)*(1+CP20) -> 1 | CR20: =J20+N20+R20+V20+Z20+AD20+AH20+AL20+AP20+AT20+AX20+BB20+BF20+BJ20+BN20+BR20+BV20+BZ20+CD20+CH20+CL20 -> 0
A21: 17-2072 Electronics Engineers, Except Computer | C21: Senior (>10 yrs) | I21: =H21*CQ21 -> 0 | J21: =G21*I21 -> 0 | M21: =L21*CQ21 -> 0 | N21: =K21*M21 -> 0 | Q21: =P21*CQ21 -> 0 | R21: =O21*Q21 -> 0 | U21: =T21*CQ21 -> 0 | V21: =S21*U21 -> 0 | Y21: =X21*CT21 -> 0 | Z21: =W21*Y21 -> 0 | AC21: =AB21*CW21 -> 0 | AD21: =AA21*AC21 -> 0 | AG21: =AF21*CZ21 -> 0 | AH21: =AE21*AG21 -> 0 | AK21: =AJ21*CQ21 -> 0 | AL21: =AI21*AK21 -> 0 | AO21: =AN21*CQ21 -> 0 | AP21: =AM21*AO21 -> 0 | AS21: =AR21*CQ21 -> 0 | AT21: =AQ21*AS21 -> 0 | AW21: =AV21*CQ21 -> 0 | AX21: =AU21*AW21 -> 0 | BA21: =AZ21*CQ21 -> 0 | BB21: =AY21*BA21 -> 0 | BE21: =BD21*CQ21 -> 0 | BF21: =BC21*BE21 -> 0 | BI21: =BH21*CQ21 -> 0 | BJ21: =BG21*BI21 -> 0 | BM21: =BL21*CQ21 -> 0 | BN21: =BK21*BM21 -> 0 | BQ21: =BP21*CQ21 -> 0 | BR21: =BO21*BQ21 -> 0 | BU21: =BT21*CQ21 -> 0 | BV21: =BS21*BU21 -> 0 | BY21: =BX21*CQ21 -> 0 | BZ21: =BW21*BY21 -> 0 | CC21: =CB21*CQ21 -> 0 | CD21: =CA21*CC21 -> 0 | CG21: =CF21*CQ21 -> 0 | CH21: =CE21*CG21 -> 0 | CK21: =CJ21*CQ21 -> 0 | CL21: =CI21*CK21 -> 0 | CQ21: =(1+CM21)*(1+CN21)*(1+CO21)*(1+CP21) -> 1 | CR21: =J21+N21+R21+V21+Z21+AD21+AH21+AL21+AP21+AT21+AX21+BB21+BF21+BJ21+BN21+BR21+BV21+BZ21+CD21+CH21+CL21 -> 0
A22: 15-2051 Data Scientists | C22: Senior (>10 yrs) | I22: =H22*CQ22 -> 0 | J22: =G22*I22 -> 0 | M22: =L22*CQ22 -> 0 | N22: =K22*M22 -> 0 | Q22: =P22*CQ22 -> 0 | R22: =O22*Q22 -> 0 | U22: =T22*CQ22 -> 0 | V22: =S22*U22 -> 0 | Y22: =X22*CT22 -> 0 | Z22: =W22*Y22 -> 0 | AC22: =AB22*CW22 -> 0 | AD22: =AA22*AC22 -> 0 | AG22: =AF22*CZ22 -> 0 | AH22: =AE22*AG22 -> 0 | AI22: 960 | AK22: =AJ22*CQ22 -> 0 | AL22: =AI22*AK22 -> 0 | AO22: =AN22*CQ22 -> 0 | AP22: =AM22*AO22 -> 0 | AS22: =AR22*CQ22 -> 0 | AT22: =AQ22*AS22 -> 0 | AW22: =AV22*CQ22 -> 0 | AX22: =AU22*AW22 -> 0 | BA22: =AZ22*CQ22 -> 0 | BB22: =AY22*BA22 -> 0 | BE22: =BD22*CQ22 -> 0 | BF22: =BC22*BE22 -> 0 | BI22: =BH22*CQ22 -> 0 | BJ22: =BG22*BI22 -> 0 | BM22: =BL22*CQ22 -> 0 | BN22: =BK22*BM22 -> 0 | BQ22: =BP22*CQ22 -> 0 | BR22: =BO22*BQ22 -> 0 | BU22: =BT22*CQ22 -> 0 | BV22: =BS22*BU22 -> 0 | BY22: =BX22*CQ22 -> 0 | BZ22: =BW22*BY22 -> 0 | CC22: =CB22*CQ22 -> 0 | CD22: =CA22*CC22 -> 0 | CG22: =CF22*CQ22 -> 0 | CH22: =CE22*CG22 -> 0 | CK22: =CJ22*CQ22 -> 0 | CL22: =CI22*CK22 -> 0 | CQ22: =(1+CM22)*(1+CN22)*(1+CO22)*(1+CP22) -> 1 | CR22: =J22+N22+R22+V22+Z22+AD22+AH22+AL22+AP22+AT22+AX22+BB22+BF22+BJ22+BN22+BR22+BV22+BZ22+CD22+CH22+CL22 -> 0
A23: 15-1299 Computer Occupations, All Other | C23: Senior (>10 yrs) | I23: =H23*CQ23 -> 0 | J23: =G23*I23 -> 0 | K23: 960 | M23: =L23*CQ23 -> 0 | N23: =K23*M23 -> 0 | Q23: =P23*CQ23 -> 0 | R23: =O23*Q23 -> 0 | U23: =T23*CQ23 -> 0 | V23: =S23*U23 -> 0 | Y23: =X23*CT23 -> 0 | Z23: =W23*Y23 -> 0 | AC23: =AB23*CW23 -> 0 | AD23: =AA23*AC23 -> 0 | AG23: =AF23*CZ23 -> 0 | AH23: =AE23*AG23 -> 0 | AK23: =AJ23*CQ23 -> 0 | AL23: =AI23*AK23 -> 0 | AO23: =AN23*CQ23 -> 0 | AP23: =AM23*AO23 -> 0 | AS23: =AR23*CQ23 -> 0 | AT23: =AQ23*AS23 -> 0 | AW23: =AV23*CQ23 -> 0 | AX23: =AU23*AW23 -> 0 | BA23: =AZ23*CQ23 -> 0 | BB23: =AY23*BA23 -> 0 | BE23: =BD23*CQ23 -> 0 | BF23: =BC23*BE23 -> 0 | BI23: =BH23*CQ23 -> 0 | BJ23: =BG23*BI23 -> 0 | BM23: =BL23*CQ23 -> 0 | BN23: =BK23*BM23 -> 0 | BQ23: =BP23*CQ23 -> 0 | BR23: =BO23*BQ23 -> 0 | BU23: =BT23*CQ23 -> 0 | BV23: =BS23*BU23 -> 0 | BY23: =BX23*CQ23 -> 0 | BZ23: =BW23*BY23 -> 0 | CC23: =CB23*CQ23 -> 0 | CD23: =CA23*CC23 -> 0 | CG23: =CF23*CQ23 -> 0 | CH23: =CE23*CG23 -> 0 | CK23: =CJ23*CQ23 -> 0 | CL23: =CI23*CK23 -> 0 | CQ23: =(1+CM23)*(1+CN23)*(1+CO23)*(1+CP23) -> 1 | CR23: =J23+N23+R23+V23+Z23+AD23+AH23+AL23+AP23+AT23+AX23+BB23+BF23+BJ23+BN23+BR23+BV23+BZ23+CD23+CH23+CL23 -> 0
A24: 15-1253 Software Quality Assurance Analysts and Testers | C24: Journeyman (3–10 yrs) | I24: =H24*CQ24 -> 0 | J24: =G24*I24 -> 0 | M24: =L24*CQ24 -> 0 | N24: =K24*M24 -> 0 | O24: 960 | Q24: =P24*CQ24 -> 0 | R24: =O24*Q24 -> 0 | U24: =T24*CQ24 -> 0 | V24: =S24*U24 -> 0 | Y24: =X24*CT24 -> 0 | Z24: =W24*Y24 -> 0 | AC24: =AB24*CW24 -> 0 | AD24: =AA24*AC24 -> 0 | AG24: =AF24*CZ24 -> 0 | AH24: =AE24*AG24 -> 0 | AK24: =AJ24*CQ24 -> 0 | AL24: =AI24*AK24 -> 0 | AO24: =AN24*CQ24 -> 0 | AP24: =AM24*AO24 -> 0 | AS24: =AR24*CQ24 -> 0 | AT24: =AQ24*AS24 -> 0 | AW24: =AV24*CQ24 -> 0 | AX24: =AU24*AW24 -> 0 | BA24: =AZ24*CQ24 -> 0 | BB24: =AY24*BA24 -> 0 | BE24: =BD24*CQ24 -> 0 | BF24: =BC24*BE24 -> 0 | BI24: =BH24*CQ24 -> 0 | BJ24: =BG24*BI24 -> 0 | BM24: =BL24*CQ24 -> 0 | BN24: =BK24*BM24 -> 0 | BQ24: =BP24*CQ24 -> 0 | BR24: =BO24*BQ24 -> 0 | BU24: =BT24*CQ24 -> 0 | BV24: =BS24*BU24 -> 0 | BY24: =BX24*CQ24 -> 0 | BZ24: =BW24*BY24 -> 0 | CC24: =CB24*CQ24 -> 0 | CD24: =CA24*CC24 -> 0 | CG24: =CF24*CQ24 -> 0 | CH24: =CE24*CG24 -> 0 | CK24: =CJ24*CQ24 -> 0 | CL24: =CI24*CK24 -> 0 | CQ24: =(1+CM24)*(1+CN24)*(1+CO24)*(1+CP24) -> 1 | CR24: =J24+N24+R24+V24+Z24+AD24+AH24+AL24+AP24+AT24+AX24+BB24+BF24+BJ24+BN24+BR24+BV24+BZ24+CD24+CH24+CL24 -> 0
A25: 15-1253 Software Quality Assurance Analysts and Testers | C25: Senior (>10 yrs) | I25: =H25*CQ25 -> 0 | J25: =G25*I25 -> 0 | M25: =L25*CQ25 -> 0 | N25: =K25*M25 -> 0 | O25: 1920 | Q25: =P25*CQ25 -> 0 | R25: =O25*Q25 -> 0 | U25: =T25*CQ25 -> 0 | V25: =S25*U25 -> 0 | Y25: =X25*CT25 -> 0 | Z25: =W25*Y25 -> 0 | AC25: =AB25*CW25 -> 0 | AD25: =AA25*AC25 -> 0 | AG25: =AF25*CZ25 -> 0 | AH25: =AE25*AG25 -> 0 | AK25: =AJ25*CQ25 -> 0 | AL25: =AI25*AK25 -> 0 | AO25: =AN25*CQ25 -> 0 | AP25: =AM25*AO25 -> 0 | AS25: =AR25*CQ25 -> 0 | AT25: =AQ25*AS25 -> 0 | AW25: =AV25*CQ25 -> 0 | AX25: =AU25*AW25 -> 0 | BA25: =AZ25*CQ25 -> 0 | BB25: =AY25*BA25 -> 0 | BE25: =BD25*CQ25 -> 0 | BF25: =BC25*BE25 -> 0 | BI25: =BH25*CQ25 -> 0 | BJ25: =BG25*BI25 -> 0 | BM25: =BL25*CQ25 -> 0 | BN25: =BK25*BM25 -> 0 | BQ25: =BP25*CQ25 -> 0 | BR25: =BO25*BQ25 -> 0 | BU25: =BT25*CQ25 -> 0 | BV25: =BS25*BU25 -> 0 | BY25: =BX25*CQ25 -> 0 | BZ25: =BW25*BY25 -> 0 | CC25: =CB25*CQ25 -> 0 | CD25: =CA25*CC25 -> 0 | CG25: =CF25*CQ25 -> 0 | CH25: =CE25*CG25 -> 0 | CK25: =CJ25*CQ25 -> 0 | CL25: =CI25*CK25 -> 0 | CQ25: =(1+CM25)*(1+CN25)*(1+CO25)*(1+CP25) -> 1 | CR25: =J25+N25+R25+V25+Z25+AD25+AH25+AL25+AP25+AT25+AX25+BB25+BF25+BJ25+BN25+BR25+BV25+BZ25+CD25+CH25+CL25 -> 0
A26: 15-1252 Software Developer | C26: Senior (>10 yrs) | I26: =H26*CQ26 -> 0 | J26: =G26*I26 -> 0 | M26: =L26*CQ26 -> 0 | N26: =K26*M26 -> 0 | Q26: =P26*CQ26 -> 0 | R26: =O26*Q26 -> 0 | U26: =T26*CQ26 -> 0 | V26: =S26*U26 -> 0 | Y26: =X26*CT26 -> 0 | Z26: =W26*Y26 -> 0 | AC26: =AB26*CW26 -> 0 | AD26: =AA26*AC26 -> 0 | AG26: =AF26*CZ26 -> 0 | AH26: =AE26*AG26 -> 0 | AK26: =AJ26*CQ26 -> 0 | AL26: =AI26*AK26 -> 0 | AO26: =AN26*CQ26 -> 0 | AP26: =AM26*AO26 -> 0 | AS26: =AR26*CQ26 -> 0 | AT26: =AQ26*AS26 -> 0 | AW26: =AV26*CQ26 -> 0 | AX26: =AU26*AW26 -> 0 | BA26: =AZ26*CQ26 -> 0 | BB26: =AY26*BA26 -> 0 | BE26: =BD26*CQ26 -> 0 | BF26: =BC26*BE26 -> 0 | BI26: =BH26*CQ26 -> 0 | BJ26: =BG26*BI26 -> 0 | BM26: =BL26*CQ26 -> 0 | BN26: =BK26*BM26 -> 0 | BQ26: =BP26*CQ26 -> 0 | BR26: =BO26*BQ26 -> 0 | BU26: =BT26*CQ26 -> 0 | BV26: =BS26*BU26 -> 0 | BW26: 960 | BY26: =BX26*CQ26 -> 0 | BZ26: =BW26*BY26 -> 0 | CC26: =CB26*CQ26 -> 0 | CD26: =CA26*CC26 -> 0 | CG26: =CF26*CQ26 -> 0 | CH26: =CE26*CG26 -> 0 | CK26: =CJ26*CQ26 -> 0 | CL26: =CI26*CK26 -> 0 | CQ26: =(1+CM26)*(1+CN26)*(1+CO26)*(1+CP26) -> 1 | CR26: =J26+N26+R26+V26+Z26+AD26+AH26+AL26+AP26+AT26+AX26+BB26+BF26+BJ26+BN26+BR26+BV26+BZ26+CD26+CH26+CL26 -> 0
A27: 15-1244 Network and Computer Systems Administrators | C27: Senior (>10 yrs) | I27: =H27*CQ27 -> 0 | J27: =G27*I27 -> 0 | N27: =K27*M27 -> 0 | O27: 1920 | Q27: =P27*CQ27 -> 0 | R27: =O27*Q27 -> 0 | U27: =T27*CQ27 -> 0 | V27: =S27*U27 -> 0 | Y27: =X27*CT27 -> 0 | Z27: =W27*Y27 -> 0 | AC27: =AB27*CW27 -> 0 | AD27: =AA27*AC27 -> 0 | AG27: =AF27*CZ27 -> 0 | AH27: =AE27*AG27 -> 0 | AK27: =AJ27*CQ27 -> 0 | AL27: =AI27*AK27 -> 0 | AO27: =AN27*CQ27 -> 0 | AP27: =AM27*AO27 -> 0 | AS27: =AR27*CQ27 -> 0 | AT27: =AQ27*AS27 -> 0 | AW27: =AV27*CQ27 -> 0 | AX27: =AU27*AW27 -> 0 | BA27: =AZ27*CQ27 -> 0 | BB27: =AY27*BA27 -> 0 | BE27: =BD27*CQ27 -> 0 | BF27: =BC27*BE27 -> 0 | BI27: =BH27*CQ27 -> 0 | BJ27: =BG27*BI27 -> 0 | BM27: =BL27*CQ27 -> 0 | BN27: =BK27*BM27 -> 0 | BQ27: =BP27*CQ27 -> 0 | BR27: =BO27*BQ27 -> 0 | BU27: =BT27*CQ27 -> 0 | BV27: =BS27*BU27 -> 0 | BY27: =BX27*CQ27 -> 0 | BZ27: =BW27*BY27 -> 0 | CC27: =CB27*CQ27 -> 0 | CD27: =CA27*CC27 -> 0 | CG27: =CF27*CQ27 -> 0 | CH27: =CE27*CG27 -> 0 | CK27: =CJ27*CQ27 -> 0 | CL27: =CI27*CK27 -> 0 | CQ27: =(1+CM27)*(1+CN27)*(1+CO27)*(1+CP27) -> 1 | CR27: =J27+N27+R27+V27+Z27+AD27+AH27+AL27+AP27+AT27+AX27+BB27+BF27+BJ27+BN27+BR27+BV27+BZ27+CD27+CH27+CL27 -> 0
A28: 15-1242 Database Administrators | C28: Senior (>10 yrs) | I28: =H28*CQ28 -> 0 | J28: =G28*I28 -> 0 | K28: 960 | M28: =L28*CQ28 -> 0 | N28: =K28*M28 -> 0 | Q28: =P28*CQ28 -> 0 | R28: =O28*Q28 -> 0 | U28: =T28*CQ28 -> 0 | V28: =S28*U28 -> 0 | Y28: =X28*CT28 -> 0 | Z28: =W28*Y28 -> 0 | AC28: =AB28*CW28 -> 0 | AD28: =AA28*AC28 -> 0 | AG28: =AF28*CZ28 -> 0 | AH28: =AE28*AG28 -> 0 | AK28: =AJ28*CQ28 -> 0 | AL28: =AI28*AK28 -> 0 | AO28: =AN28*CQ28 -> 0 | AP28: =AM28*AO28 -> 0 | AS28: =AR28*CQ28 -> 0 | AT28: =AQ28*AS28 -> 0 | AW28: =AV28*CQ28 -> 0 | AX28: =AU28*AW28 -> 0 | BA28: =AZ28*CQ28 -> 0 | BB28: =AY28*BA28 -> 0 | BE28: =BD28*CQ28 -> 0 | BF28: =BC28*BE28 -> 0 | BI28: =BH28*CQ28 -> 0 | BJ28: =BG28*BI28 -> 0 | BM28: =BL28*CQ28 -> 0 | BN28: =BK28*BM28 -> 0 | BQ28: =BP28*CQ28 -> 0 | BR28: =BO28*BQ28 -> 0 | BU28: =BT28*CQ28 -> 0 | BV28: =BS28*BU28 -> 0 | BY28: =BX28*CQ28 -> 0 | BZ28: =BW28*BY28 -> 0 | CC28: =CB28*CQ28 -> 0 | CD28: =CA28*CC28 -> 0 | CG28: =CF28*CQ28 -> 0 | CH28: =CE28*CG28 -> 0 | CK28: =CJ28*CQ28 -> 0 | CL28: =CI28*CK28 -> 0 | CQ28: =(1+CM28)*(1+CN28)*(1+CO28)*(1+CP28) -> 1 | CR28: =J28+N28+R28+V28+Z28+AD28+AH28+AL28+AP28+AT28+AX28+BB28+BF28+BJ28+BN28+BR28+BV28+BZ28+CD28+CH28+CL28 -> 0
A29: 15-1232 Computer User Support Specialists | C29: Journeyman (3–10 yrs) | I29: =H29*CQ29 -> 0 | J29: =G29*I29 -> 0 | M29: =L29*CQ29 -> 0 | N29: =K29*M29 -> 0 | O29: 960 | Q29: =P29*CQ29 -> 0 | R29: =O29*Q29 -> 0 | U29: =T29*CQ29 -> 0 | V29: =S29*U29 -> 0 | Y29: =X29*CT29 -> 0 | Z29: =W29*Y29 -> 0 | AC29: =AB29*CW29 -> 0 | AD29: =AA29*AC29 -> 0 | AG29: =AF29*CZ29 -> 0 | AH29: =AE29*AG29 -> 0 | AK29: =AJ29*CQ29 -> 0 | AL29: =AI29*AK29 -> 0 | AO29: =AN29*CQ29 -> 0 | AP29: =AM29*AO29 -> 0 | AS29: =AR29*CQ29 -> 0 | AT29: =AQ29*AS29 -> 0 | AW29: =AV29*CQ29 -> 0 | AX29: =AU29*AW29 -> 0 | BA29: =AZ29*CQ29 -> 0 | BB29: =AY29*BA29 -> 0 | BE29: =BD29*CQ29 -> 0 | BF29: =BC29*BE29 -> 0 | BI29: =BH29*CQ29 -> 0 | BJ29: =BG29*BI29 -> 0 | BM29: =BL29*CQ29 -> 0 | BN29: =BK29*BM29 -> 0 | BQ29: =BP29*CQ29 -> 0 | BR29: =BO29*BQ29 -> 0 | BU29: =BT29*CQ29 -> 0 | BV29: =BS29*BU29 -> 0 | BY29: =BX29*CQ29 -> 0 | BZ29: =BW29*BY29 -> 0 | CC29: =CB29*CQ29 -> 0 | CD29: =CA29*CC29 -> 0 | CG29: =CF29*CQ29 -> 0 | CH29: =CE29*CG29 -> 0 | CK29: =CJ29*CQ29 -> 0 | CL29: =CI29*CK29 -> 0 | CQ29: =(1+CM29)*(1+CN29)*(1+CO29)*(1+CP29) -> 1 | CR29: =J29+N29+R29+V29+Z29+AD29+AH29+AL29+AP29+AT29+AX29+BB29+BF29+BJ29+BN29+BR29+BV29+BZ29+CD29+CH29+CL29 -> 0
A30: 15-1231 Computer Network Support Specialists | C30: Senior (>10 yrs) | I30: =H30*CQ30 -> 0 | J30: =G30*I30 -> 0 | M30: =L30*CQ30 -> 0 | N30: =K30*M30 -> 0 | O30: 960 | Q30: =P30*CQ30 -> 0 | R30: =O30*Q30 -> 0 | U30: =T30*CQ30 -> 0 | V30: =S30*U30 -> 0 | Y30: =X30*CT30 -> 0 | Z30: =W30*Y30 -> 0 | AC30: =AB30*CW30 -> 0 | AD30: =AA30*AC30 -> 0 | AG30: =AF30*CZ30 -> 0 | AH30: =AE30*AG30 -> 0 | AK30: =AJ30*CQ30 -> 0 | AL30: =AI30*AK30 -> 0 | AO30: =AN30*CQ30 -> 0 | AP30: =AM30*AO30 -> 0 | AS30: =AR30*CQ30 -> 0 | AT30: =AQ30*AS30 -> 0 | AW30: =AV30*CQ30 -> 0 | AX30: =AU30*AW30 -> 0 | BA30: =AZ30*CQ30 -> 0 | BB30: =AY30*BA30 -> 0 | BE30: =BD30*CQ30 -> 0 | BF30: =BC30*BE30 -> 0 | BI30: =BH30*CQ30 -> 0 | BJ30: =BG30*BI30 -> 0 | BM30: =BL30*CQ30 -> 0 | BN30: =BK30*BM30 -> 0 | BQ30: =BP30*CQ30 -> 0 | BR30: =BO30*BQ30 -> 0 | BU30: =BT30*CQ30 -> 0 | BV30: =BS30*BU30 -> 0 | BY30: =BX30*CQ30 -> 0 | BZ30: =BW30*BY30 -> 0 | CC30: =CB30*CQ30 -> 0 | CD30: =CA30*CC30 -> 0 | CG30: =CF30*CQ30 -> 0 | CH30: =CE30*CG30 -> 0 | CK30: =CJ30*CQ30 -> 0 | CL30: =CI30*CK30 -> 0 | CQ30: =(1+CM30)*(1+CN30)*(1+CO30)*(1+CP30) -> 1 | CR30: =J30+N30+R30+V30+Z30+AD30+AH30+AL30+AP30+AT30+AX30+BB30+BF30+BJ30+BN30+BR30+BV30+BZ30+CD30+CH30+CL30 -> 0
A31: 15-1212 Information Security Analysts | C31: Senior (>10 yrs) | G31: 480 | I31: =H31*CQ31 -> 0 | J31: =G31*I31 -> 0 | M31: =L31*CQ31 -> 0 | N31: =K31*M31 -> 0 | O31: 960 | Q31: =P31*CQ31 -> 0 | R31: =O31*Q31 -> 0 | U31: =T31*CQ31 -> 0 | V31: =S31*U31 -> 0 | Y31: =X31*CT31 -> 0 | Z31: =W31*Y31 -> 0 | AC31: =AB31*CW31 -> 0 | AD31: =AA31*AC31 -> 0 | AG31: =AF31*CZ31 -> 0 | AH31: =AE31*AG31 -> 0 | AK31: =AJ31*CQ31 -> 0 | AL31: =AI31*AK31 -> 0 | AO31: =AN31*CQ31 -> 0 | AP31: =AM31*AO31 -> 0 | AS31: =AR31*CQ31 -> 0 | AT31: =AQ31*AS31 -> 0 | AW31: =AV31*CQ31 -> 0 | AX31: =AU31*AW31 -> 0 | BA31: =AZ31*CQ31 -> 0 | BB31: =AY31*BA31 -> 0 | BE31: =BD31*CQ31 -> 0 | BF31: =BC31*BE31 -> 0 | BI31: =BH31*CQ31 -> 0 | BJ31: =BG31*BI31 -> 0 | BM31: =BL31*CQ31 -> 0 | BN31: =BK31*BM31 -> 0 | BQ31: =BP31*CQ31 -> 0 | BR31: =BO31*BQ31 -> 0 | BU31: =BT31*CQ31 -> 0 | BV31: =BS31*BU31 -> 0 | BY31: =BX31*CQ31 -> 0 | BZ31: =BW31*BY31 -> 0 | CC31: =CB31*CQ31 -> 0 | CD31: =CA31*CC31 -> 0 | CG31: =CF31*CQ31 -> 0 | CH31: =CE31*CG31 -> 0 | CK31: =CJ31*CQ31 -> 0 | CL31: =CI31*CK31 -> 0 | CQ31: =(1+CM31)*(1+CN31)*(1+CO31)*(1+CP31) -> 1 | CR31: =J31+N31+R31+V31+Z31+AD31+AH31+AL31+AP31+AT31+AX31+BB31+BF31+BJ31+BN31+BR31+BV31+BZ31+CD31+CH31+CL31 -> 0
A32: 15-1211 Computer Systems Analysts | C32: Journeyman (3–10 yrs) | I32: =H32*CQ32 -> 0 | J32: =G32*I32 -> 0 | M32: =L32*CQ32 -> 0 | N32: =K32*M32 -> 0 | O32: 960 | Q32: =P32*CQ32 -> 0 | R32: =O32*Q32 -> 0 | U32: =T32*CQ32 -> 0 | V32: =S32*U32 -> 0 | Y32: =X32*CT32 -> 0 | Z32: =W32*Y32 -> 0 | AC32: =AB32*CW32 -> 0 | AD32: =AA32*AC32 -> 0 | AG32: =AF32*CZ32 -> 0 | AH32: =AE32*AG32 -> 0 | AK32: =AJ32*CQ32 -> 0 | AL32: =AI32*AK32 -> 0 | AO32: =AN32*CQ32 -> 0 | AP32: =AM32*AO32 -> 0 | AS32: =AR32*CQ32 -> 0 | AT32: =AQ32*AS32 -> 0 | AW32: =AV32*CQ32 -> 0 | AX32: =AU32*AW32 -> 0 | BA32: =AZ32*CQ32 -> 0 | BB32: =AY32*BA32 -> 0 | BE32: =BD32*CQ32 -> 0 | BF32: =BC32*BE32 -> 0 | BI32: =BH32*CQ32 -> 0 | BJ32: =BG32*BI32 -> 0 | BM32: =BL32*CQ32 -> 0 | BN32: =BK32*BM32 -> 0 | BQ32: =BP32*CQ32 -> 0 | BR32: =BO32*BQ32 -> 0 | BU32: =BT32*CQ32 -> 0 | BV32: =BS32*BU32 -> 0 | BY32: =BX32*CQ32 -> 0 | BZ32: =BW32*BY32 -> 0 | CC32: =CB32*CQ32 -> 0 | CD32: =CA32*CC32 -> 0 | CG32: =CF32*CQ32 -> 0 | CH32: =CE32*CG32 -> 0 | CK32: =CJ32*CQ32 -> 0 | CL32: =CI32*CK32 -> 0 | CQ32: =(1+CM32)*(1+CN32)*(1+CO32)*(1+CP32) -> 1 | CR32: =J32+N32+R32+V32+Z32+AD32+AH32+AL32+AP32+AT32+AX32+BB32+BF32+BJ32+BN32+BR32+BV32+BZ32+CD32+CH32+CL32 -> 0
A33: 15-1211 Computer Systems Analysts | C33: Senior (>10 yrs) | I33: =H33*CQ33 -> 0 | J33: =G33*I33 -> 0 | M33: =L33*CQ33 -> 0 | N33: =K33*M33 -> 0 | Q33: =P33*CQ33 -> 0 | R33: =O33*Q33 -> 0 | U33: =T33*CQ33 -> 0 | V33: =S33*U33 -> 0 | Y33: =X33*CT33 -> 0 | Z33: =W33*Y33 -> 0 | AC33: =AB33*CW33 -> 0 | AD33: =AA33*AC33 -> 0 | AG33: =AF33*CZ33 -> 0 | AH33: =AE33*AG33 -> 0 | AI33: 960 | AK33: =AJ33*CQ33 -> 0 | AL33: =AI33*AK33 -> 0 | AO33: =AN33*CQ33 -> 0 | AP33: =AM33*AO33 -> 0 | AS33: =AR33*CQ33 -> 0 | AT33: =AQ33*AS33 -> 0 | AW33: =AV33*CQ33 -> 0 | AX33: =AU33*AW33 -> 0 | BA33: =AZ33*CQ33 -> 0 | BB33: =AY33*BA33 -> 0 | BE33: =BD33*CQ33 -> 0 | BF33: =BC33*BE33 -> 0 | BI33: =BH33*CQ33 -> 0 | BJ33: =BG33*BI33 -> 0 | BM33: =BL33*CQ33 -> 0 | BN33: =BK33*BM33 -> 0 | BQ33: =BP33*CQ33 -> 0 | BR33: =BO33*BQ33 -> 0 | BU33: =BT33*CQ33 -> 0 | BV33: =BS33*BU33 -> 0 | BY33: =BX33*CQ33 -> 0 | BZ33: =BW33*BY33 -> 0 | CC33: =CB33*CQ33 -> 0 | CD33: =CA33*CC33 -> 0 | CG33: =CF33*CQ33 -> 0 | CH33: =CE33*CG33 -> 0 | CK33: =CJ33*CQ33 -> 0 | CL33: =CI33*CK33 -> 0 | CQ33: =(1+CM33)*(1+CN33)*(1+CO33)*(1+CP33) -> 1 | CR33: =J33+N33+R33+V33+Z33+AD33+AH33+AL33+AP33+AT33+AX33+BB33+BF33+BJ33+BN33+BR33+BV33+BZ33+CD33+CH33+CL33 -> 0
A34: 13-2031 - Budget Analyst | C34: Journeyman (3-10 yrs) | G34: 960 | I34: =H34*CQ34 -> 0 | J34: =G34*I34 -> 0 | M34: =L34*CQ34 -> 0 | N34: =K34*M34 -> 0 | Q34: =P34*CQ34 -> 0 | R34: =O34*Q34 -> 0 | U34: =T34*CQ34 -> 0 | V34: =S34*U34 -> 0 | Y34: =X34*CT34 -> 0 | Z34: =W34*Y34 -> 0 | AC34: =AB34*CW34 -> 0 | AD34: =AA34*AC34 -> 0 | AG34: =AF34*CZ34 -> 0 | AH34: =AE34*AG34 -> 0 | AK34: =AJ34*CQ34 -> 0 | AL34: =AI34*AK34 -> 0 | AO34: =AN34*CQ34 -> 0 | AP34: =AM34*AO34 -> 0 | AS34: =AR34*CQ34 -> 0 | AT34: =AQ34*AS34 -> 0 | AW34: =AV34*CQ34 -> 0 | AX34: =AU34*AW34 -> 0 | BA34: =AZ34*CQ34 -> 0 | BB34: =AY34*BA34 -> 0 | BE34: =BD34*CQ34 -> 0 | BF34: =BC34*BE34 -> 0 | BI34: =BH34*CQ34 -> 0 | BJ34: =BG34*BI34 -> 0 | BM34: =BL34*CQ34 -> 0 | BN34: =BK34*BM34 -> 0 | BQ34: =BP34*CQ34 -> 0 | BR34: =BO34*BQ34 -> 0 | BU34: =BT34*CQ34 -> 0 | BV34: =BS34*BU34 -> 0 | BY34: =BX34*CQ34 -> 0 | BZ34: =BW34*BY34 -> 0 | CC34: =CB34*CQ34 -> 0 | CD34: =CA34*CC34 -> 0 | CG34: =CF34*CQ34 -> 0 | CH34: =CE34*CG34 -> 0 | CK34: =CJ34*CQ34 -> 0 | CL34: =CI34*CK34 -> 0 | CQ34: =(1+CM34)*(1+CN34)*(1+CO34)*(1+CP34) -> 1 | CR34: =J34+N34+R34+V34+Z34+AD34+AH34+AL34+AP34+AT34+AX34+BB34+BF34+BJ34+BN34+BR34+BV34+BZ34+CD34+CH34+CL34 -> 0
A35: 13-1151 Training and Development Specialists | C35: Subject Matter Expert (SME) | I35: =H35*CQ35 -> 0 | J35: =G35*I35 -> 0 | K35: 5760 | M35: =L35*CQ35 -> 0 | N35: =K35*M35 -> 0 | Q35: =P35*CQ35 -> 0 | R35: =O35*Q35 -> 0 | U35: =T35*CQ35 -> 0 | V35: =S35*U35 -> 0 | Y35: =X35*CT35 -> 0 | Z35: =W35*Y35 -> 0 | AC35: =AB35*CW35 -> 0 | AD35: =AA35*AC35 -> 0 | AG35: =AF35*CZ35 -> 0 | AH35: =AE35*AG35 -> 0 | AK35: =AJ35*CQ35 -> 0 | AL35: =AI35*AK35 -> 0 | AM35: 960 | AO35: =AN35*CQ35 -> 0 | AP35: =AM35*AO35 -> 0 | AS35: =AR35*CQ35 -> 0 | AT35: =AQ35*AS35 -> 0 | AW35: =AV35*CQ35 -> 0 | AX35: =AU35*AW35 -> 0 | BA35: =AZ35*CQ35 -> 0 | BB35: =AY35*BA35 -> 0 | BE35: =BD35*CQ35 -> 0 | BF35: =BC35*BE35 -> 0 | BI35: =BH35*CQ35 -> 0 | BJ35: =BG35*BI35 -> 0 | BM35: =BL35*CQ35 -> 0 | BN35: =BK35*BM35 -> 0 | BQ35: =BP35*CQ35 -> 0 | BR35: =BO35*BQ35 -> 0 | BU35: =BT35*CQ35 -> 0 | BV35: =BS35*BU35 -> 0 | BY35: =BX35*CQ35 -> 0 | BZ35: =BW35*BY35 -> 0 | CC35: =CB35*CQ35 -> 0 | CD35: =CA35*CC35 -> 0 | CG35: =CF35*CQ35 -> 0 | CH35: =CE35*CG35 -> 0 | CK35: =CJ35*CQ35 -> 0 | CL35: =CI35*CK35 -> 0 | CQ35: =(1+CM35)*(1+CN35)*(1+CO35)*(1+CP35) -> 1 | CR35: =J35+N35+R35+V35+Z35+AD35+AH35+AL35+AP35+AT35+AX35+BB35+BF35+BJ35+BN35+BR35+BV35+BZ35+CD35+CH35+CL35 -> 0
A36: 13-1151 Training and Development Specialists | C36: Journeyman (3–10 yrs) | G36: 1920 | I36: =H36*CQ36 -> 0 | J36: =G36*I36 -> 0 | M36: =L36*CQ36 -> 0 | N36: =K36*M36 -> 0 | Q36: =P36*CQ36 -> 0 | R36: =O36*Q36 -> 0 | U36: =T36*CQ36 -> 0 | V36: =S36*U36 -> 0 | Y36: =X36*CT36 -> 0 | Z36: =W36*Y36 -> 0 | AC36: =AB36*CW36 -> 0 | AD36: =AA36*AC36 -> 0 | AG36: =AF36*CZ36 -> 0 | AH36: =AE36*AG36 -> 0 | AK36: =AJ36*CQ36 -> 0 | AL36: =AI36*AK36 -> 0 | AO36: =AN36*CQ36 -> 0 | AP36: =AM36*AO36 -> 0 | AS36: =AR36*CQ36 -> 0 | AT36: =AQ36*AS36 -> 0 | AW36: =AV36*CQ36 -> 0 | AX36: =AU36*AW36 -> 0 | BA36: =AZ36*CQ36 -> 0 | BB36: =AY36*BA36 -> 0 | BE36: =BD36*CQ36 -> 0 | BF36: =BC36*BE36 -> 0 | BI36: =BH36*CQ36 -> 0 | BJ36: =BG36*BI36 -> 0 | BM36: =BL36*CQ36 -> 0 | BN36: =BK36*BM36 -> 0 | BQ36: =BP36*CQ36 -> 0 | BR36: =BO36*BQ36 -> 0 | BU36: =BT36*CQ36 -> 0 | BV36: =BS36*BU36 -> 0 | BY36: =BX36*CQ36 -> 0 | BZ36: =BW36*BY36 -> 0 | CC36: =CB36*CQ36 -> 0 | CD36: =CA36*CC36 -> 0 | CG36: =CF36*CQ36 -> 0 | CH36: =CE36*CG36 -> 0 | CK36: =CJ36*CQ36 -> 0 | CL36: =CI36*CK36 -> 0 | CQ36: =(1+CM36)*(1+CN36)*(1+CO36)*(1+CP36) -> 1 | CR36: =J36+N36+R36+V36+Z36+AD36+AH36+AL36+AP36+AT36+AX36+BB36+BF36+BJ36+BN36+BR36+BV36+BZ36+CD36+CH36+CL36 -> 0
A37: 13-1151 Training and Development Specialists | C37: Senior (>10 yrs) | G37: 5760 | I37: =H37*CQ37 -> 0 | J37: =G37*I37 -> 0 | K37: 960 | M37: =L37*CQ37 -> 0 | N37: =K37*M37 -> 0 | Q37: =P37*CQ37 -> 0 | R37: =O37*Q37 -> 0 | U37: =T37*CQ37 -> 0 | V37: =S37*U37 -> 0 | Y37: =X37*CT37 -> 0 | Z37: =W37*Y37 -> 0 | AC37: =AB37*CW37 -> 0 | AD37: =AA37*AC37 -> 0 | AG37: =AF37*CZ37 -> 0 | AH37: =AE37*AG37 -> 0 | AI37: 960 | AK37: =AJ37*CQ37 -> 0 | AL37: =AI37*AK37 -> 0 | AO37: =AN37*CQ37 -> 0 | AP37: =AM37*AO37 -> 0 | AS37: =AR37*CQ37 -> 0 | AT37: =AQ37*AS37 -> 0 | AW37: =AV37*CQ37 -> 0 | AX37: =AU37*AW37 -> 0 | BA37: =AZ37*CQ37 -> 0 | BB37: =AY37*BA37 -> 0 | BE37: =BD37*CQ37 -> 0 | BF37: =BC37*BE37 -> 0 | BI37: =BH37*CQ37 -> 0 | BJ37: =BG37*BI37 -> 0 | BM37: =BL37*CQ37 -> 0 | BN37: =BK37*BM37 -> 0 | BQ37: =BP37*CQ37 -> 0 | BR37: =BO37*BQ37 -> 0 | BU37: =BT37*CQ37 -> 0 | BV37: =BS37*BU37 -> 0 | BY37: =BX37*CQ37 -> 0 | BZ37: =BW37*BY37 -> 0 | CC37: =CB37*CQ37 -> 0 | CD37: =CA37*CC37 -> 0 | CG37: =CF37*CQ37 -> 0 | CH37: =CE37*CG37 -> 0 | CK37: =CJ37*CQ37 -> 0 | CL37: =CI37*CK37 -> 0 | CQ37: =(1+CM37)*(1+CN37)*(1+CO37)*(1+CP37) -> 1 | CR37: =J37+N37+R37+V37+Z37+AD37+AH37+AL37+AP37+AT37+AX37+BB37+BF37+BJ37+BN37+BR37+BV37+BZ37+CD37+CH37+CL37 -> 0
A38: 13-11199 - Business Operations Specialist | C38: Junior (<3 years) | I38: =H38*CQ38 -> 0 | J38: =G38*I38 -> 0 | M38: =L38*CQ38 -> 0 | N38: =K38*M38 -> 0 | Q38: =P38*CQ38 -> 0 | R38: =O38*Q38 -> 0 | U38: =T38*CQ38 -> 0 | V38: =S38*U38 -> 0 | Y38: =X38*CT38 -> 0 | Z38: =W38*Y38 -> 0 | AC38: =AB38*CW38 -> 0 | AD38: =AA38*AC38 -> 0 | AG38: =AF38*CZ38 -> 0 | AH38: =AE38*AG38 -> 0 | AK38: =AJ38*CQ38 -> 0 | AL38: =AI38*AK38 -> 0 | AO38: =AN38*CQ38 -> 0 | AP38: =AM38*AO38 -> 0 | AQ38: 1920 | AS38: =AR38*CQ38 -> 0 | AT38: =AQ38*AS38 -> 0 | AW38: =AV38*CQ38 -> 0 | AX38: =AU38*AW38 -> 0 | BA38: =AZ38*CQ38 -> 0 | BB38: =AY38*BA38 -> 0 | BE38: =BD38*CQ38 -> 0 | BF38: =BC38*BE38 -> 0 | BI38: =BH38*CQ38 -> 0 | BJ38: =BG38*BI38 -> 0 | BM38: =BL38*CQ38 -> 0 | BN38: =BK38*BM38 -> 0 | BQ38: =BP38*CQ38 -> 0 | BR38: =BO38*BQ38 -> 0 | BU38: =BT38*CQ38 -> 0 | BV38: =BS38*BU38 -> 0 | BY38: =BX38*CQ38 -> 0 | BZ38: =BW38*BY38 -> 0 | CC38: =CB38*CQ38 -> 0 | CD38: =CA38*CC38 -> 0 | CG38: =CF38*CQ38 -> 0 | CH38: =CE38*CG38 -> 0 | CK38: =CJ38*CQ38 -> 0 | CL38: =CI38*CK38 -> 0 | CQ38: =(1+CM38)*(1+CN38)*(1+CO38)*(1+CP38) -> 1 | CR38: =J38+N38+R38+V38+Z38+AD38+AH38+AL38+AP38+AT38+AX38+BB38+BF38+BJ38+BN38+BR38+BV38+BZ38+CD38+CH38+CL38 -> 0
A39: 13-1111 Management Analysts | C39: Subject Matter Expert (SME) | G39: 2880 | I39: =H39*CQ39 -> 0 | J39: =G39*I39 -> 0 | M39: =L39*CQ39 -> 0 | N39: =K39*M39 -> 0 | Q39: =P39*CQ39 -> 0 | R39: =O39*Q39 -> 0 | U39: =T39*CQ39 -> 0 | V39: =S39*U39 -> 0 | Y39: =X39*CT39 -> 0 | Z39: =W39*Y39 -> 0 | AC39: =AB39*CW39 -> 0 | AD39: =AA39*AC39 -> 0 | AG39: =AF39*CZ39 -> 0 | AH39: =AE39*AG39 -> 0 | AK39: =AJ39*CQ39 -> 0 | AL39: =AI39*AK39 -> 0 | AO39: =AN39*CQ39 -> 0 | AP39: =AM39*AO39 -> 0 | AS39: =AR39*CQ39 -> 0 | AT39: =AQ39*AS39 -> 0 | AU39: 960 | AW39: =AV39*CQ39 -> 0 | AX39: =AU39*AW39 -> 0 | AY39: 960 | BA39: =AZ39*CQ39 -> 0 | BB39: =AY39*BA39 -> 0 | BC39: 4800 | BE39: =BD39*CQ39 -> 0 | BF39: =BC39*BE39 -> 0 | BI39: =BH39*CQ39 -> 0 | BJ39: =BG39*BI39 -> 0 | BM39: =BL39*CQ39 -> 0 | BN39: =BK39*BM39 -> 0 | BQ39: =BP39*CQ39 -> 0 | BR39: =BO39*BQ39 -> 0 | BU39: =BT39*CQ39 -> 0 | BV39: =BS39*BU39 -> 0 | BY39: =BX39*CQ39 -> 0 | BZ39: =BW39*BY39 -> 0 | CC39: =CB39*CQ39 -> 0 | CD39: =CA39*CC39 -> 0 | CG39: =CF39*CQ39 -> 0 | CH39: =CE39*CG39 -> 0 | CK39: =CJ39*CQ39 -> 0 | CL39: =CI39*CK39 -> 0 | CQ39: =(1+CM39)*(1+CN39)*(1+CO39)*(1+CP39) -> 1 | CR39: =J39+N39+R39+V39+Z39+AD39+AH39+AL39+AP39+AT39+AX39+BB39+BF39+BJ39+BN39+BR39+BV39+BZ39+CD39+CH39+CL39 -> 0
A40: 13-1111 Management Analysts | C40: Senior (>10 yrs) | G40: 960 | I40: =H40*CQ40 -> 0 | J40: =G40*I40 -> 0 | M40: =L40*CQ40 -> 0 | N40: =K40*M40 -> 0 | O40: 12480 | Q40: =P40*CQ40 -> 0 | R40: =O40*Q40 -> 0 | U40: =T40*CQ40 -> 0 | V40: =S40*U40 -> 0 | Y40: =X40*CT40 -> 0 | Z40: =W40*Y40 -> 0 | AC40: =AB40*CW40 -> 0 | AD40: =AA40*AC40 -> 0 | AG40: =AF40*CZ40 -> 0 | AH40: =AE40*AG40 -> 0 | AI40: 2880 | AK40: =AJ40*CQ40 -> 0 | AL40: =AI40*AK40 -> 0 | AO40: =AN40*CQ40 -> 0 | AP40: =AM40*AO40 -> 0 | AS40: =AR40*CQ40 -> 0 | AT40: =AQ40*AS40 -> 0 | AW40: =AV40*CQ40 -> 0 | AX40: =AU40*AW40 -> 0 | BA40: =AZ40*CQ40 -> 0 | BB40: =AY40*BA40 -> 0 | BE40: =BD40*CQ40 -> 0 | BF40: =BC40*BE40 -> 0 | BI40: =BH40*CQ40 -> 0 | BJ40: =BG40*BI40 -> 0 | BM40: =BL40*CQ40 -> 0 | BN40: =BK40*BM40 -> 0 | BQ40: =BP40*CQ40 -> 0 | BR40: =BO40*BQ40 -> 0 | BU40: =BT40*CQ40 -> 0 | BV40: =BS40*BU40 -> 0 | BY40: =BX40*CQ40 -> 0 | BZ40: =BW40*BY40 -> 0 | CC40: =CB40*CQ40 -> 0 | CD40: =CA40*CC40 -> 0 | CG40: =CF40*CQ40 -> 0 | CH40: =CE40*CG40 -> 0 | CK40: =CJ40*CQ40 -> 0 | CL40: =CI40*CK40 -> 0 | CQ40: =(1+CM40)*(1+CN40)*(1+CO40)*(1+CP40) -> 1 | CR40: =J40+N40+R40+V40+Z40+AD40+AH40+AL40+AP40+AT40+AX40+BB40+BF40+BJ40+BN40+BR40+BV40+BZ40+CD40+CH40+CL40 -> 0
A41: 13-1111 Management Analysts | C41: Journeyman (3–10 yrs) | I41: =H41*CQ41 -> 0 | J41: =G41*I41 -> 0 | M41: =L41*CQ41 -> 0 | N41: =K41*M41 -> 0 | O41: 5760 | Q41: =P41*CQ41 -> 0 | R41: =O41*Q41 -> 0 | U41: =T41*CQ41 -> 0 | V41: =S41*U41 -> 0 | Y41: =X41*CT41 -> 0 | Z41: =W41*Y41 -> 0 | AC41: =AB41*CW41 -> 0 | AD41: =AA41*AC41 -> 0 | AG41: =AF41*CZ41 -> 0 | AH41: =AE41*AG41 -> 0 | AK41: =AJ41*CQ41 -> 0 | AL41: =AI41*AK41 -> 0 | AO41: =AN41*CQ41 -> 0 | AP41: =AM41*AO41 -> 0 | AS41: =AR41*CQ41 -> 0 | AT41: =AQ41*AS41 -> 0 | AW41: =AV41*CQ41 -> 0 | AX41: =AU41*AW41 -> 0 | BA41: =AZ41*CQ41 -> 0 | BB41: =AY41*BA41 -> 0 | BE41: =BD41*CQ41 -> 0 | BF41: =BC41*BE41 -> 0 | BI41: =BH41*CQ41 -> 0 | BJ41: =BG41*BI41 -> 0 | BM41: =BL41*CQ41 -> 0 | BN41: =BK41*BM41 -> 0 | BQ41: =BP41*CQ41 -> 0 | BR41: =BO41*BQ41 -> 0 | BU41: =BT41*CQ41 -> 0 | BV41: =BS41*BU41 -> 0 | BY41: =BX41*CQ41 -> 0 | BZ41: =BW41*BY41 -> 0 | CC41: =CB41*CQ41 -> 0 | CD41: =CA41*CC41 -> 0 | CE41: 960 | CG41: =CF41*CQ41 -> 0 | CH41: =CE41*CG41 -> 0 | CK41: =CJ41*CQ41 -> 0 | CL41: =CI41*CK41 -> 0 | CQ41: =(1+CM41)*(1+CN41)*(1+CO41)*(1+CP41) -> 1 | CR41: =J41+N41+R41+V41+Z41+AD41+AH41+AL41+AP41+AT41+AX41+BB41+BF41+BJ41+BN41+BR41+BV41+BZ41+CD41+CH41+CL41 -> 0
A42: 13-1082 Project Management Specialists | C42: Subject Matter Expert (SME) | G42: 2880 | I42: =H42*CQ42 -> 0 | J42: =G42*I42 -> 0 | M42: =L42*CQ42 -> 0 | N42: =K42*M42 -> 0 | Q42: =P42*CQ42 -> 0 | R42: =O42*Q42 -> 0 | U42: =T42*CQ42 -> 0 | V42: =S42*U42 -> 0 | W42: 960 | Y42: =X42*CT42 -> 0 | Z42: =W42*Y42 -> 0 | AC42: =AB42*CW42 -> 0 | AD42: =AA42*AC42 -> 0 | AG42: =AF42*CZ42 -> 0 | AH42: =AE42*AG42 -> 0 | AK42: =AJ42*CQ42 -> 0 | AL42: =AI42*AK42 -> 0 | AO42: =AN42*CQ42 -> 0 | AP42: =AM42*AO42 -> 0 | AS42: =AR42*CQ42 -> 0 | AT42: =AQ42*AS42 -> 0 | AW42: =AV42*CQ42 -> 0 | AX42: =AU42*AW42 -> 0 | BA42: =AZ42*CQ42 -> 0 | BB42: =AY42*BA42 -> 0 | BE42: =BD42*CQ42 -> 0 | BF42: =BC42*BE42 -> 0 | BI42: =BH42*CQ42 -> 0 | BJ42: =BG42*BI42 -> 0 | BM42: =BL42*CQ42 -> 0 | BN42: =BK42*BM42 -> 0 | BQ42: =BP42*CQ42 -> 0 | BR42: =BO42*BQ42 -> 0 | BU42: =BT42*CQ42 -> 0 | BV42: =BS42*BU42 -> 0 | BY42: =BX42*CQ42 -> 0 | BZ42: =BW42*BY42 -> 0 | CC42: =CB42*CQ42 -> 0 | CD42: =CA42*CC42 -> 0 | CG42: =CF42*CQ42 -> 0 | CH42: =CE42*CG42 -> 0 | CK42: =CJ42*CQ42 -> 0 | CL42: =CI42*CK42 -> 0 | CQ42: =(1+CM42)*(1+CN42)*(1+CO42)*(1+CP42) -> 1 | CR42: =J42+N42+R42+V42+Z42+AD42+AH42+AL42+AP42+AT42+AX42+BB42+BF42+BJ42+BN42+BR42+BV42+BZ42+CD42+CH42+CL42 -> 0
A43: 13-1082 Project Management Specialists | C43: Journeyman (3–10 yrs) | G43: 960 | I43: =H43*CQ43 -> 0 | J43: =G43*I43 -> 0 | M43: =L43*CQ43 -> 0 | N43: =K43*M43 -> 0 | O43: 2880 | Q43: =P43*CQ43 -> 0 | R43: =O43*Q43 -> 0 | U43: =T43*CQ43 -> 0 | V43: =S43*U43 -> 0 | Y43: =X43*CT43 -> 0 | Z43: =W43*Y43 -> 0 | AC43: =AB43*CW43 -> 0 | AD43: =AA43*AC43 -> 0 | AG43: =AF43*CZ43 -> 0 | AH43: =AE43*AG43 -> 0 | AI43: 3840 | AK43: =AJ43*CQ43 -> 0 | AL43: =AI43*AK43 -> 0 | AO43: =AN43*CQ43 -> 0 | AP43: =AM43*AO43 -> 0 | AS43: =AR43*CQ43 -> 0 | AT43: =AQ43*AS43 -> 0 | AW43: =AV43*CQ43 -> 0 | AX43: =AU43*AW43 -> 0 | BA43: =AZ43*CQ43 -> 0 | BB43: =AY43*BA43 -> 0 | BE43: =BD43*CQ43 -> 0 | BF43: =BC43*BE43 -> 0 | BI43: =BH43*CQ43 -> 0 | BJ43: =BG43*BI43 -> 0 | BM43: =BL43*CQ43 -> 0 | BN43: =BK43*BM43 -> 0 | BQ43: =BP43*CQ43 -> 0 | BR43: =BO43*BQ43 -> 0 | BU43: =BT43*CQ43 -> 0 | BV43: =BS43*BU43 -> 0 | BW43: 480 | BY43: =BX43*CQ43 -> 0 | BZ43: =BW43*BY43 -> 0 | CC43: =CB43*CQ43 -> 0 | CD43: =CA43*CC43 -> 0 | CG43: =CF43*CQ43 -> 0 | CH43: =CE43*CG43 -> 0 | CK43: =CJ43*CQ43 -> 0 | CL43: =CI43*CK43 -> 0 | CQ43: =(1+CM43)*(1+CN43)*(1+CO43)*(1+CP43) -> 1 | CR43: =J43+N43+R43+V43+Z43+AD43+AH43+AL43+AP43+AT43+AX43+BB43+BF43+BJ43+BN43+BR43+BV43+BZ43+CD43+CH43+CL43 -> 0
A44: 13-1082 Project Management Specialists | C44: Senior (>10 yrs) | G44: 960 | I44: =H44*CQ44 -> 0 | J44: =G44*I44 -> 0 | M44: =L44*CQ44 -> 0 | N44: =K44*M44 -> 0 | O44: 23040 | Q44: =P44*CQ44 -> 0 | R44: =O44*Q44 -> 0 | U44: =T44*CQ44 -> 0 | V44: =S44*U44 -> 0 | Y44: =X44*CT44 -> 0 | Z44: =W44*Y44 -> 0 | AA44: 960 | AC44: =AB44*CW44 -> 0 | AD44: =AA44*AC44 -> 0 | AE44: 960 | AG44: =AF44*CZ44 -> 0 | AH44: =AE44*AG44 -> 0 | AI44: 6720 | AK44: =AJ44*CQ44 -> 0 | AL44: =AI44*AK44 -> 0 | AO44: =AN44*CQ44 -> 0 | AP44: =AM44*AO44 -> 0 | AS44: =AR44*CQ44 -> 0 | AT44: =AQ44*AS44 -> 0 | AW44: =AV44*CQ44 -> 0 | AX44: =AU44*AW44 -> 0 | BA44: =AZ44*CQ44 -> 0 | BB44: =AY44*BA44 -> 0 | BE44: =BD44*CQ44 -> 0 | BF44: =BC44*BE44 -> 0 | BG44: 960 | BI44: =BH44*CQ44 -> 0 | BJ44: =BG44*BI44 -> 0 | BK44: 960 | BM44: =BL44*CQ44 -> 0 | BN44: =BK44*BM44 -> 0 | BO44: 960 | BQ44: =BP44*CQ44 -> 0 | BR44: =BO44*BQ44 -> 0 | BS44: 960 | BU44: =BT44*CQ44 -> 0 | BV44: =BS44*BU44 -> 0 | BY44: =BX44*CQ44 -> 0 | BZ44: =BW44*BY44 -> 0 | CC44: =CB44*CQ44 -> 0 | CD44: =CA44*CC44 -> 0 | CG44: =CF44*CQ44 -> 0 | CH44: =CE44*CG44 -> 0 | CK44: =CJ44*CQ44 -> 0 | CL44: =CI44*CK44 -> 0 | CQ44: =(1+CM44)*(1+CN44)*(1+CO44)*(1+CP44) -> 1 | CR44: =J44+N44+R44+V44+Z44+AD44+AH44+AL44+AP44+AT44+AX44+BB44+BF44+BJ44+BN44+BR44+BV44+BZ44+CD44+CH44+CL44 -> 0
A45: 13-1081 Logisticians | C45: Subject Matter Expert (SME) | I45: =H45*CQ45 -> 0 | J45: =G45*I45 -> 0 | M45: =L45*CQ45 -> 0 | N45: =K45*M45 -> 0 | Q45: =P45*CQ45 -> 0 | R45: =O45*Q45 -> 0 | S45: 960 | U45: =T45*CQ45 -> 0 | V45: =S45*U45 -> 0 | Y45: =X45*CT45 -> 0 | Z45: =W45*Y45 -> 0 | AC45: =AB45*CW45 -> 0 | AD45: =AA45*AC45 -> 0 | AG45: =AF45*CZ45 -> 0 | AH45: =AE45*AG45 -> 0 | AK45: =AJ45*CQ45 -> 0 | AL45: =AI45*AK45 -> 0 | AO45: =AN45*CQ45 -> 0 | AP45: =AM45*AO45 -> 0 | AS45: =AR45*CQ45 -> 0 | AT45: =AQ45*AS45 -> 0 | AW45: =AV45*CQ45 -> 0 | AX45: =AU45*AW45 -> 0 | BA45: =AZ45*CQ45 -> 0 | BB45: =AY45*BA45 -> 0 | BE45: =BD45*CQ45 -> 0 | BF45: =BC45*BE45 -> 0 | BI45: =BH45*CQ45 -> 0 | BJ45: =BG45*BI45 -> 0 | BM45: =BL45*CQ45 -> 0 | BN45: =BK45*BM45 -> 0 | BQ45: =BP45*CQ45 -> 0 | BR45: =BO45*BQ45 -> 0 | BU45: =BT45*CQ45 -> 0 | BV45: =BS45*BU45 -> 0 | BY45: =BX45*CQ45 -> 0 | BZ45: =BW45*BY45 -> 0 | CC45: =CB45*CQ45 -> 0 | CD45: =CA45*CC45 -> 0 | CG45: =CF45*CQ45 -> 0 | CH45: =CE45*CG45 -> 0 | CK45: =CJ45*CQ45 -> 0 | CL45: =CI45*CK45 -> 0 | CQ45: =(1+CM45)*(1+CN45)*(1+CO45)*(1+CP45) -> 1 | CR45: =J45+N45+R45+V45+Z45+AD45+AH45+AL45+AP45+AT45+AX45+BB45+BF45+BJ45+BN45+BR45+BV45+BZ45+CD45+CH45+CL45 -> 0
...

Sheet Option Period 1
A1: Option Period 1
A2: Contract Period | B2: Period of Performance Start Date | C2: Period of Performance End Date | F2: Escalation Rate | G2: Total
A3: Option Period 1 | B3: 46614 | C3: 46979 | F3: 0 | G3: =Q59 -> 0
A6: Direct Labor
A10: Occupation | B10: Offeror Labor Category | C10: GSA Occupation Level | D10: Escalation Applied (Y/N) | E10: SCA Exempt (Y/N) | F10: SCA Base Rate | G10: SIM HRS Orlando | H10: SIM Rate | I10: SIM Rate Burdened | J10: SIM Subtotal | K10: SIM HRS Ft Campbell | L10: SIM Ft. Campbell Rate | M10: SIM Ft. Campbell Burdened | N10: SIM Ft. Campell Subtotal | O10: TRADE HRS Orlando | P10: TRADE Rate | Q10: TRADE Rate Burdened | R10: TRADE Subtotal | S10: TRADE HRS Germany | T10: TRADE Rate Germany | U10: TRADE Rate Germany Burdened | V10: TRADE Germany Subtotal | W10: TRADE HRS Ft. Hood | X10: TRADE Rate Ft. Hood | Y10: TRADE Rate Ft Hood Burdened | Z10: TRADE Ft. Hood Subtotal | AA10: TRADE HRS Ft. Irwin | AB10: TRADE Rate Ft. Irwin | AC10: TRADE Rate Ft. Irwin Burdened | AD10: TRADE Ft. Irwin Subtotal | AE10: TRADE HRS Ft. Polk | AF10: TRADE Rate Ft. Polk | AG10: TRADE Rate Ft. Polk Burdened | AH10: TRADE Ft. Polk Subtotal | AI10: IPO HRS Orlando | AJ10: IPO Rate | AK10: IPO Rate Burdened | AL10: IPO Subtotal | AM10: IPO HRS Ft. Campbell | AN10: IPO Ft. Campbell Rate | AO10: IPO Rate Ft. Campbell Burdened | AP10: IPO Ft. Campbell Subtotal | AQ10: TSO HRS Orlando | AR10: TSO Rate | AS10: TSO Rate Burdened | AT10: TSO Subtotal | AU10: TSO HRS Ft. Bragg | AV10: TSO Rate Ft. Bragg | AW10: TSO Rate Ft. Bragg Burdened | AX10: TSO Ft. Bragg Subtotal | AY10: TSO HRS Ft Drum | AZ10: TSO Rate Ft. Drum | BA10: TSO Rate Ft. Drum Burdened | BB10: TSO Ft. Drum Subtotal | BC10: TSO HRS Ft. Rucker | BD10: TSO Rate Ft. Rucker | BE10: TSO Rate Ft. Rucker Burdened | BF10: TSO Ft. Rucker Subtotal | BG10: TSO HRS Ft. Polk | BH10: TSO Rate Ft. Polk | BI10: TSO Rate Ft. Polk Burdened | BJ10: TSO Ft. Polk Subtotal | BK10: TSO HRS Ft. Irwin | BL10: TSO Rate Ft. Irwin | BM10: TSO Rate Ft. Irwin Burdened | BN10: TSO Ft. Irwin Subtotal | BO10: TSO HRS Germany | BP10: TSO Rate Germany | BQ10: TSO Rate Germany Burdened | BR10: TSO Germany Subtotal | BS10: TSO HRS S. Korea | BT10: TSO Rate S. Korea | BU10: TSO Rate S. Korea Burdened | BV10: TSO S. Korea Subtotal | BW10: HQ HRS (Orlando, FL) | BX10: HQ Rate | BY10: HQ Rate Burdened | BZ10: HQ Subtotal | CA10: TSMO HRS Orlando | CB10: TSMO Rate | CC10: TSMO Rate Burdened | CD10: TSMO Subtotal | CE10: TSMO HRS Huntsville, AL | CF10: TSMO Huntsville, AL. Rate | CG10: Huntsville, Alabama Rate (Burdened) | CH10: TSO Huntsville, AL Subtotal | CI10: ADMIN HRS (Location) | CJ10: ADMIN Rate | CK10: Admin Rate Burdened | CL10: Admin Subtotal | CM10: Fringe % | CN10: Overhead % | CO10: G&A % | CP10: Profit % | CQ10: Burden Rate | CR10: Total
A11: 49-9099 Installation, Maintenance, and Repair Workers, All Other | C11: Subject Matter Expert (SME) | I11: =H11*CQ11 -> 0 | J11: =G11*I11 -> 0 | M11: =L11*CQ11 -> 0 | N11: =K11*M11 -> 0 | Q11: =P11*CQ11 -> 0 | R11: =O11*Q11 -> 0 | U11: =T11*CQ11 -> 0 | V11: =S11*U11 -> 0 | Y11: =X11*CQ11 -> 0 | Z11: =W11*Y11 -> 0 | AC11: =AB11*CQ11 -> 0 | AD11: =AA11*AC11 -> 0 | AG11: =AF11*CQ11 -> 0 | AH11: =AE11*AG11 -> 0 | AK11: =AJ11*CQ11 -> 0 | AL11: =AI11*AK11 -> 0 | AO11: =AN11*CQ11 -> 0 | AP11: =AM11*AO11 -> 0 | AS11: =AR11*CQ11 -> 0 | AT11: =AQ11*AS11 -> 0 | AW11: 0 | AX11: 0 | BA11: 0 | BB11: 0 | BE11: 0 | BF11: 0 | BI11: 0 | BJ11: 0 | BM11: 0 | BN11: 0 | BQ11: 0 | BR11: 0 | BU11: =BT11*CQ11 -> 0 | BV11: =BS11*BU11 -> 0 | BW11: 480 | BY11: =BX11*CQ11 -> 0 | BZ11: =BW11*BY11 -> 0 | CC11: 0 | CD11: 0 | CG11: =CF11*CQ11 -> 0 | CH11: =CE11*CG11 -> 0 | CK11: =CJ11*CQ11 -> 0 | CL11: =CI11*CK11 -> 0 | CM11: 0.1 | CN11: 0.15 | CO11: 0.05 | CP11: 0.1 | CQ11: =(1+CM11)*(1+CN11)*(1+CO11)*(1+CP11) -> 1.461075 | CR11: =J11+N11+R11+V11+Z11+AD11+AH11+AL11+AP11+AT11+AX11+BB11+BF11+BJ11+BN11+BR11+BV11+BZ11+CD11+CH11+CL11 -> 0
A12: 49-9099 Installation, Maintenance, and Repair Workers, All Other | C12: Journeyman (3–10 yrs) | I12: =H12*CQ12 -> 0 | J12: =G12*I12 -> 0 | M12: =L12*CQ12 -> 0 | N12: =K12*M12 -> 0 | Q12: =P12*CQ12 -> 0 | R12: =O12*Q12 -> 0 | U12: =T12*CQ12 -> 0 | V12: =S12*U12 -> 0 | Y12: =X12*CT12 -> 0 | Z12: =W12*Y12 -> 0 | AC12: =AB12*CW12 -> 0 | AD12: =AA12*AC12 -> 0 | AG12: =AF12*CZ12 -> 0 | AH12: =AE12*AG12 -> 0 | AK12: =AJ12*CQ12 -> 0 | AL12: =AI12*AK12 -> 0 | AO12: =AN12*CQ12 -> 0 | AP12: =AM12*AO12 -> 0 | AS12: =AR12*CQ12 -> 0 | AT12: =AQ12*AS12 -> 0 | AW12: 0 | AX12: 0 | BA12: 0 | BB12: 0 | BE12: 0 | BF12: 0 | BI12: 0 | BJ12: 0 | BM12: 0 | BN12: 0 | BQ12: 0 | BR12: 0 | BU12: =BT12*CQ12 -> 0 | BV12: =BS12*BU12 -> 0 | BW12: 480 | BY12: =BX12*CQ12 -> 0 | BZ12: =BW12*BY12 -> 0 | CC12: 0 | CD12: 0 | CG12: =CF12*CQ12 -> 0 | CH12: =CE12*CG12 -> 0 | CK12: =CJ12*CQ12 -> 0 | CL12: =CI12*CK12 -> 0 | CQ12: =(1+CM12)*(1+CN12)*(1+CO12)*(1+CP12) -> 1 | CR12: =J12+N12+R12+V12+Z12+AD12+AH12+AL12+AP12+AT12+AX12+BB12+BF12+BJ12+BN12+BR12+BV12+BZ12+CD12+CH12+CL12 -> 0
A13: 27-3042 Technical Writers | C13: Journeyman (3–10 yrs) | I13: =H13*CQ13 -> 0 | J13: =G13*I13 -> 0 | M13: =L13*CQ13 -> 0 | N13: =K13*M13 -> 0 | O13: 3840 | Q13: =P13*CQ13 -> 0 | R13: =O13*Q13 -> 0 | U13: =T13*CQ13 -> 0 | V13: =S13*U13 -> 0 | Y13: =X13*CT13 -> 0 | Z13: =W13*Y13 -> 0 | AC13: =AB13*CW13 -> 0 | AD13: =AA13*AC13 -> 0 | AG13: =AF13*CZ13 -> 0 | AH13: =AE13*AG13 -> 0 | AK13: =AJ13*CQ13 -> 0 | AL13: =AI13*AK13 -> 0 | AO13: =AN13*CQ13 -> 0 | AP13: =AM13*AO13 -> 0 | AS13: =AR13*CQ13 -> 0 | AT13: =AQ13*AS13 -> 0 | AW13: 0 | AX13: 0 | BA13: 0 | BB13: 0 | BE13: 0 | BF13: 0 | BI13: 0 | BJ13: 0 | BM13: 0 | BN13: 0 | BQ13: 0 | BR13: 0 | BU13: =BT13*CQ13 -> 0 | BV13: =BS13*BU13 -> 0 | BY13: =BX13*CQ13 -> 0 | BZ13: =BW13*BY13 -> 0 | CC13: 0 | CD13: 0 | CG13: =CF13*CQ13 -> 0 | CH13: =CE13*CG13 -> 0 | CK13: =CJ13*CQ13 -> 0 | CL13: =CI13*CK13 -> 0 | CQ13: =(1+CM13)*(1+CN13)*(1+CO13)*(1+CP13) -> 1 | CR13: =J13+N13+R13+V13+Z13+AD13+AH13+AL13+AP13+AT13+AX13+BB13+BF13+BJ13+BN13+BR13+BV13+BZ13+CD13+CH13+CL13 -> 0
A14: 27-3042 Technical Writers | C14: Senior (>10 yrs) | I14: =H14*CQ14 -> 0 | J14: =G14*I14 -> 0 | M14: =L14*CQ14 -> 0 | N14: =K14*M14 -> 0 | O14: 1920 | Q14: =P14*CQ14 -> 0 | R14: =O14*Q14 -> 0 | U14: =T14*CQ14 -> 0 | V14: =S14*U14 -> 0 | Y14: =X14*CT14 -> 0 | Z14: =W14*Y14 -> 0 | AC14: =AB14*CW14 -> 0 | AD14: =AA14*AC14 -> 0 | AG14: =AF14*CZ14 -> 0 | AH14: =AE14*AG14 -> 0 | AK14: =AJ14*CQ14 -> 0 | AL14: =AI14*AK14 -> 0 | AO14: =AN14*CQ14 -> 0 | AP14: =AM14*AO14 -> 0 | AS14: =AR14*CQ14 -> 0 | AT14: =AQ14*AS14 -> 0 | AW14: 0 | AX14: 0 | BA14: 0 | BB14: 0 | BE14: 0 | BF14: 0 | BI14: 0 | BJ14: 0 | BM14: 0 | BN14: 0 | BQ14: 0 | BR14: 0 | BU14: =BT14*CQ14 -> 0 | BV14: =BS14*BU14 -> 0 | BY14: =BX14*CQ14 -> 0 | BZ14: =BW14*BY14 -> 0 | CC14: 0 | CD14: 0 | CG14: =CF14*CQ14 -> 0 | CH14: =CE14*CG14 -> 0 | CK14: =CJ14*CQ14 -> 0 | CL14: =CI14*CK14 -> 0 | CQ14: =(1+CM14)*(1+CN14)*(1+CO14)*(1+CP14) -> 1 | CR14: =J14+N14+R14+V14+Z14+AD14+AH14+AL14+AP14+AT14+AX14+BB14+BF14+BJ14+BN14+BR14+BV14+BZ14+CD14+CH14+CL14 -> 0
A15: 27-3031 Public Relations Specialists** | C15: Senior (>10 yrs) | I15: =H15*CQ15 -> 0 | J15: =G15*I15 -> 0 | M15: =L15*CQ15 -> 0 | N15: =K15*M15 -> 0 | Q15: =P15*CQ15 -> 0 | R15: =O15*Q15 -> 0 | U15: =T15*CQ15 -> 0 | V15: =S15*U15 -> 0 | Y15: =X15*CT15 -> 0 | Z15: =W15*Y15 -> 0 | AC15: =AB15*CW15 -> 0 | AD15: =AA15*AC15 -> 0 | AG15: =AF15*CZ15 -> 0 | AH15: =AE15*AG15 -> 0 | AK15: =AJ15*CQ15 -> 0 | AL15: =AI15*AK15 -> 0 | AO15: =AN15*CQ15 -> 0 | AP15: =AM15*AO15 -> 0 | AS15: =AR15*CQ15 -> 0 | AT15: =AQ15*AS15 -> 0 | AW15: 0 | AX15: 0 | BA15: 0 | BB15: 0 | BE15: 0 | BF15: 0 | BI15: 0 | BJ15: 0 | BM15: 0 | BN15: 0 | BQ15: 0 | BR15: 0 | BU15: =BT15*CQ15 -> 0 | BV15: =BS15*BU15 -> 0 | BY15: =BX15*CQ15 -> 0 | BZ15: =BW15*BY15 -> 0 | CC15: 0 | CD15: 0 | CG15: =CF15*CQ15 -> 0 | CH15: =CE15*CG15 -> 0 | CK15: =CJ15*CQ15 -> 0 | CL15: =CI15*CK15 -> 0 | CQ15: =(1+CM15)*(1+CN15)*(1+CO15)*(1+CP15) -> 1 | CR15: =J15+N15+R15+V15+Z15+AD15+AH15+AL15+AP15+AT15+AX15+BB15+BF15+BJ15+BN15+BR15+BV15+BZ15+CD15+CH15+CL15 -> 0
A16: 17-3029 Engineering Technologists and Technicians | C16: Senior (>10 yrs) | I16: =H16*CQ16 -> 0 | J16: =G16*I16 -> 0 | M16: =L16*CQ16 -> 0 | N16: =K16*M16 -> 0 | Q16: =P16*CQ16 -> 0 | R16: =O16*Q16 -> 0 | U16: =T16*CQ16 -> 0 | V16: =S16*U16 -> 0 | Y16: =X16*CT16 -> 0 | Z16: =W16*Y16 -> 0 | AC16: =AB16*CW16 -> 0 | AD16: =AA16*AC16 -> 0 | AG16: =AF16*CZ16 -> 0 | AH16: =AE16*AG16 -> 0 | AK16: =AJ16*CQ16 -> 0 | AL16: =AI16*AK16 -> 0 | AO16: =AN16*CQ16 -> 0 | AP16: =AM16*AO16 -> 0 | AS16: =AR16*CQ16 -> 0 | AT16: =AQ16*AS16 -> 0 | AW16: 0 | AX16: 0 | BA16: 0 | BB16: 0 | BE16: 0 | BF16: 0 | BI16: 0 | BJ16: 0 | BM16: 0 | BN16: 0 | BQ16: 0 | BR16: 0 | BU16: =BT16*CQ16 -> 0 | BV16: =BS16*BU16 -> 0 | BY16: =BX16*CQ16 -> 0 | BZ16: =BW16*BY16 -> 0 | CA16: 1920 | CC16: 0 | CD16: 0 | CG16: =CF16*CQ16 -> 0 | CH16: =CE16*CG16 -> 0 | CK16: =CJ16*CQ16 -> 0 | CL16: =CI16*CK16 -> 0 | CQ16: =(1+CM16)*(1+CN16)*(1+CO16)*(1+CP16) -> 1 | CR16: =J16+N16+R16+V16+Z16+AD16+AH16+AL16+AP16+AT16+AX16+BB16+BF16+BJ16+BN16+BR16+BV16+BZ16+CD16+CH16+CL16 -> 0
A17: 17-2199 Engineers, All Other | C17: Subject Matter Expert (SME) | G17: 1920 | I17: =H17*CQ17 -> 0 | J17: =G17*I17 -> 0 | M17: =L17*CQ17 -> 0 | N17: =K17*M17 -> 0 | Q17: =P17*CQ17 -> 0 | R17: =O17*Q17 -> 0 | U17: =T17*CQ17 -> 0 | V17: =S17*U17 -> 0 | Y17: =X17*CT17 -> 0 | Z17: =W17*Y17 -> 0 | AC17: =AB17*CW17 -> 0 | AD17: =AA17*AC17 -> 0 | AG17: =AF17*CZ17 -> 0 | AH17: =AE17*AG17 -> 0 | AK17: =AJ17*CQ17 -> 0 | AL17: =AI17*AK17 -> 0 | AO17: =AN17*CQ17 -> 0 | AP17: =AM17*AO17 -> 0 | AS17: =AR17*CQ17 -> 0 | AT17: =AQ17*AS17 -> 0 | AW17: 0 | AX17: 0 | BA17: 0 | BB17: 0 | BE17: 0 | BF17: 0 | BI17: 0 | BJ17: 0 | BM17: 0 | BN17: 0 | BQ17: 0 | BR17: 0 | BU17: =BT17*CQ17 -> 0 | BV17: =BS17*BU17 -> 0 | BY17: =BX17*CQ17 -> 0 | BZ17: =BW17*BY17 -> 0 | CC17: 0 | CD17: 0 | CG17: =CF17*CQ17 -> 0 | CH17: =CE17*CG17 -> 0 | CK17: =CJ17*CQ17 -> 0 | CL17: =CI17*CK17 -> 0 | CQ17: =(1+CM17)*(1+CN17)*(1+CO17)*(1+CP17) -> 1 | CR17: =J17+N17+R17+V17+Z17+AD17+AH17+AL17+AP17+AT17+AX17+BB17+BF17+BJ17+BN17+BR17+BV17+BZ17+CD17+CH17+CL17 -> 0
